2024-01-21 04:42:12,557 INFO    StreamThr :98834 [internal.py:wandb_internal():86] W&B internal server running at pid: 98834, started at: 2024-01-21 04:42:12.556573
2024-01-21 04:42:12,558 DEBUG   HandlerThread:98834 [handler.py:handle_request():146] handle_request: status
2024-01-21 04:42:12,561 INFO    WriterThread:98834 [datastore.py:open_for_write():87] open: /Users/suhuangyuan/DRA/wandb/run-20240121_044212-szfhwsl6/run-szfhwsl6.wandb
2024-01-21 04:42:12,562 DEBUG   SenderThread:98834 [sender.py:send():382] send: header
2024-01-21 04:42:12,587 DEBUG   SenderThread:98834 [sender.py:send():382] send: run
2024-01-21 04:42:16,233 INFO    SenderThread:98834 [retry.py:__call__():172] Retry attempt failed:
Traceback (most recent call last):
  File "/Users/suhuangyuan/miniconda3/envs/resource/lib/python3.9/site-packages/urllib3/connectionpool.py", line 467, in _make_request
    self._validate_conn(conn)
  File "/Users/suhuangyuan/miniconda3/envs/resource/lib/python3.9/site-packages/urllib3/connectionpool.py", line 1096, in _validate_conn
    conn.connect()
  File "/Users/suhuangyuan/miniconda3/envs/resource/lib/python3.9/site-packages/urllib3/connection.py", line 642, in connect
    sock_and_verified = _ssl_wrap_socket_and_match_hostname(
  File "/Users/suhuangyuan/miniconda3/envs/resource/lib/python3.9/site-packages/urllib3/connection.py", line 782, in _ssl_wrap_socket_and_match_hostname
    ssl_sock = ssl_wrap_socket(
  File "/Users/suhuangyuan/miniconda3/envs/resource/lib/python3.9/site-packages/urllib3/util/ssl_.py", line 470, in ssl_wrap_socket
    ssl_sock = _ssl_wrap_socket_impl(sock, context, tls_in_tls, server_hostname)
  File "/Users/suhuangyuan/miniconda3/envs/resource/lib/python3.9/site-packages/urllib3/util/ssl_.py", line 514, in _ssl_wrap_socket_impl
    return ssl_context.wrap_socket(sock, server_hostname=server_hostname)
  File "/Users/suhuangyuan/miniconda3/envs/resource/lib/python3.9/ssl.py", line 501, in wrap_socket
    return self.sslsocket_class._create(
  File "/Users/suhuangyuan/miniconda3/envs/resource/lib/python3.9/ssl.py", line 1074, in _create
    self.do_handshake()
  File "/Users/suhuangyuan/miniconda3/envs/resource/lib/python3.9/ssl.py", line 1343, in do_handshake
    self._sslobj.do_handshake()
ssl.SSLZeroReturnError: TLS/SSL connection has been closed (EOF) (_ssl.c:1129)

During handling of the above exception, another exception occurred:

Traceback (most recent call last):
  File "/Users/suhuangyuan/miniconda3/envs/resource/lib/python3.9/site-packages/urllib3/connectionpool.py", line 790, in urlopen
    response = self._make_request(
  File "/Users/suhuangyuan/miniconda3/envs/resource/lib/python3.9/site-packages/urllib3/connectionpool.py", line 491, in _make_request
    raise new_e
urllib3.exceptions.SSLError: TLS/SSL connection has been closed (EOF) (_ssl.c:1129)

The above exception was the direct cause of the following exception:

Traceback (most recent call last):
  File "/Users/suhuangyuan/miniconda3/envs/resource/lib/python3.9/site-packages/requests/adapters.py", line 486, in send
    resp = conn.urlopen(
  File "/Users/suhuangyuan/miniconda3/envs/resource/lib/python3.9/site-packages/urllib3/connectionpool.py", line 844, in urlopen
    retries = retries.increment(
  File "/Users/suhuangyuan/miniconda3/envs/resource/lib/python3.9/site-packages/urllib3/util/retry.py", line 515, in increment
    raise MaxRetryError(_pool, url, reason) from reason  # type: ignore[arg-type]
urllib3.exceptions.MaxRetryError: HTTPSConnectionPool(host='api.wandb.ai', port=443): Max retries exceeded with url: /graphql (Caused by SSLError(SSLZeroReturnError(6, 'TLS/SSL connection has been closed (EOF) (_ssl.c:1129)')))

During handling of the above exception, another exception occurred:

Traceback (most recent call last):
  File "/Users/suhuangyuan/miniconda3/envs/resource/lib/python3.9/site-packages/wandb/sdk/lib/retry.py", line 131, in __call__
    result = self._call_fn(*args, **kwargs)
  File "/Users/suhuangyuan/miniconda3/envs/resource/lib/python3.9/site-packages/wandb/sdk/internal/internal_api.py", line 369, in execute
    return self.client.execute(*args, **kwargs)  # type: ignore
  File "/Users/suhuangyuan/miniconda3/envs/resource/lib/python3.9/site-packages/wandb/vendor/gql-0.2.0/wandb_gql/client.py", line 52, in execute
    result = self._get_result(document, *args, **kwargs)
  File "/Users/suhuangyuan/miniconda3/envs/resource/lib/python3.9/site-packages/wandb/vendor/gql-0.2.0/wandb_gql/client.py", line 60, in _get_result
    return self.transport.execute(document, *args, **kwargs)
  File "/Users/suhuangyuan/miniconda3/envs/resource/lib/python3.9/site-packages/wandb/sdk/lib/gql_request.py", line 58, in execute
    request = self.session.post(self.url, **post_args)
  File "/Users/suhuangyuan/miniconda3/envs/resource/lib/python3.9/site-packages/requests/sessions.py", line 637, in post
    return self.request("POST", url, data=data, json=json, **kwargs)
  File "/Users/suhuangyuan/miniconda3/envs/resource/lib/python3.9/site-packages/requests/sessions.py", line 589, in request
    resp = self.send(prep, **send_kwargs)
  File "/Users/suhuangyuan/miniconda3/envs/resource/lib/python3.9/site-packages/requests/sessions.py", line 703, in send
    r = adapter.send(request, **kwargs)
  File "/Users/suhuangyuan/miniconda3/envs/resource/lib/python3.9/site-packages/requests/adapters.py", line 517, in send
    raise SSLError(e, request=request)
requests.exceptions.SSLError: HTTPSConnectionPool(host='api.wandb.ai', port=443): Max retries exceeded with url: /graphql (Caused by SSLError(SSLZeroReturnError(6, 'TLS/SSL connection has been closed (EOF) (_ssl.c:1129)')))
2024-01-21 04:42:17,611 DEBUG   HandlerThread:98834 [handler.py:handle_request():146] handle_request: keepalive
2024-01-21 04:42:22,631 DEBUG   HandlerThread:98834 [handler.py:handle_request():146] handle_request: keepalive
2024-01-21 04:42:27,649 DEBUG   HandlerThread:98834 [handler.py:handle_request():146] handle_request: keepalive
2024-01-21 04:42:32,672 DEBUG   HandlerThread:98834 [handler.py:handle_request():146] handle_request: keepalive
2024-01-21 04:42:37,693 DEBUG   HandlerThread:98834 [handler.py:handle_request():146] handle_request: keepalive
2024-01-21 04:42:42,716 DEBUG   HandlerThread:98834 [handler.py:handle_request():146] handle_request: keepalive
2024-01-21 04:42:47,734 DEBUG   HandlerThread:98834 [handler.py:handle_request():146] handle_request: keepalive
2024-01-21 04:42:52,753 DEBUG   HandlerThread:98834 [handler.py:handle_request():146] handle_request: keepalive
2024-01-21 04:42:57,778 DEBUG   HandlerThread:98834 [handler.py:handle_request():146] handle_request: keepalive
2024-01-21 04:43:02,802 DEBUG   HandlerThread:98834 [handler.py:handle_request():146] handle_request: keepalive
2024-01-21 04:43:07,822 DEBUG   HandlerThread:98834 [handler.py:handle_request():146] handle_request: keepalive
2024-01-21 04:43:12,845 DEBUG   HandlerThread:98834 [handler.py:handle_request():146] handle_request: keepalive
2024-01-21 04:43:17,868 DEBUG   HandlerThread:98834 [handler.py:handle_request():146] handle_request: keepalive
2024-01-21 04:43:22,883 DEBUG   HandlerThread:98834 [handler.py:handle_request():146] handle_request: keepalive
2024-01-21 04:43:27,902 DEBUG   HandlerThread:98834 [handler.py:handle_request():146] handle_request: keepalive
2024-01-21 04:43:32,924 DEBUG   HandlerThread:98834 [handler.py:handle_request():146] handle_request: keepalive
2024-01-21 04:43:37,946 DEBUG   HandlerThread:98834 [handler.py:handle_request():146] handle_request: keepalive
2024-01-21 04:43:42,964 DEBUG   HandlerThread:98834 [handler.py:handle_request():146] handle_request: cancel
2024-01-21 04:43:42,964 DEBUG   HandlerThread:98834 [handler.py:handle_request():146] handle_request: cancel
2024-01-21 04:43:42,964 DEBUG   SenderThread:98834 [sender.py:send():391] Record cancelled: run
2024-01-21 04:43:42,964 DEBUG   HandlerThread:98834 [handler.py:handle_request():146] handle_request: status_report
2024-01-21 04:43:43,064 DEBUG   HandlerThread:98834 [handler.py:handle_request():146] handle_request: shutdown
2024-01-21 04:43:43,064 INFO    HandlerThread:98834 [handler.py:finish():869] shutting down handler
2024-01-21 04:43:43,968 INFO    WriterThread:98834 [datastore.py:close():296] close: /Users/suhuangyuan/DRA/wandb/run-20240121_044212-szfhwsl6/run-szfhwsl6.wandb
2024-01-21 04:43:43,969 INFO    SenderThread:98834 [sender.py:finish():1572] shutting down sender
