2024-01-21 06:11:47,644 INFO    StreamThr :19058 [internal.py:wandb_internal():86] W&B internal server running at pid: 19058, started at: 2024-01-21 06:11:47.643700
2024-01-21 06:11:47,648 DEBUG   HandlerThread:19058 [handler.py:handle_request():146] handle_request: status
2024-01-21 06:11:47,648 INFO    WriterThread:19058 [datastore.py:open_for_write():87] open: /Users/suhuangyuan/DRA/wandb/run-20240121_061147-b1xmukc9/run-b1xmukc9.wandb
2024-01-21 06:11:47,649 DEBUG   SenderThread:19058 [sender.py:send():382] send: header
2024-01-21 06:11:47,673 DEBUG   SenderThread:19058 [sender.py:send():382] send: run
2024-01-21 06:11:50,953 DEBUG   HandlerThread:19058 [handler.py:handle_request():146] handle_request: check_version
2024-01-21 06:11:50,954 INFO    SenderThread:19058 [dir_watcher.py:__init__():211] watching files in: /Users/suhuangyuan/DRA/wandb/run-20240121_061147-b1xmukc9/files
2024-01-21 06:11:50,955 INFO    SenderThread:19058 [sender.py:_start_run_threads():1136] run started: b1xmukc9 with start time 1705788707.64346
2024-01-21 06:11:50,955 DEBUG   SenderThread:19058 [sender.py:send_request():409] send_request: check_version
2024-01-21 06:11:53,980 DEBUG   HandlerThread:19058 [handler.py:handle_request():146] handle_request: status_report
2024-01-21 06:11:53,984 DEBUG   HandlerThread:19058 [handler.py:handle_request():146] handle_request: run_start
2024-01-21 06:11:53,992 DEBUG   HandlerThread:19058 [system_info.py:__init__():27] System info init
2024-01-21 06:11:53,992 DEBUG   HandlerThread:19058 [system_info.py:__init__():42] System info init done
2024-01-21 06:11:53,993 INFO    HandlerThread:19058 [system_monitor.py:start():194] Starting system monitor
2024-01-21 06:11:53,993 INFO    SystemMonitor:19058 [system_monitor.py:_start():158] Starting system asset monitoring threads
2024-01-21 06:11:53,993 INFO    HandlerThread:19058 [system_monitor.py:probe():214] Collecting system info
2024-01-21 06:11:53,993 INFO    SystemMonitor:19058 [interfaces.py:start():190] Started cpu monitoring
2024-01-21 06:11:53,994 INFO    SystemMonitor:19058 [interfaces.py:start():190] Started disk monitoring
2024-01-21 06:11:53,995 INFO    SystemMonitor:19058 [interfaces.py:start():190] Started gpuapple monitoring
2024-01-21 06:11:53,995 DEBUG   HandlerThread:19058 [system_info.py:probe():151] Probing system
2024-01-21 06:11:53,998 INFO    SystemMonitor:19058 [interfaces.py:start():190] Started memory monitoring
2024-01-21 06:11:53,999 INFO    SystemMonitor:19058 [interfaces.py:start():190] Started network monitoring
2024-01-21 06:11:54,004 DEBUG   HandlerThread:19058 [system_info.py:_probe_git():136] Probing git
2024-01-21 06:11:54,040 DEBUG   HandlerThread:19058 [system_info.py:_probe_git():144] Probing git done
2024-01-21 06:11:54,040 DEBUG   HandlerThread:19058 [system_info.py:probe():199] Probing system done
2024-01-21 06:11:54,040 DEBUG   HandlerThread:19058 [system_monitor.py:probe():223] {'os': 'macOS-13.2.1-arm64-arm-64bit', 'python': '3.9.18', 'heartbeatAt': '2024-01-20T22:11:53.998264', 'startedAt': '2024-01-20T22:11:47.635294', 'docker': None, 'cuda': None, 'args': ('--env', 'RA', '--model', 'ToM2C', '--workers', '6', '--norm-reward'), 'state': 'running', 'program': '/Users/suhuangyuan/DRA/main.py', 'codePathLocal': 'main.py', 'codePath': 'main.py', 'git': {'remote': 'git@github.com:Hither1/DRA.git', 'commit': 'f62b44b4268f087957510e98676af8dc4dcc3c75'}, 'email': 'suhither@gmail.com', 'root': '/Users/suhuangyuan/DRA', 'host': 'gens-MacBook-Pro.local', 'username': 'suhuangyuan', 'executable': '/Users/suhuangyuan/miniconda3/envs/resource/bin/python', 'cpu_count': 10, 'cpu_count_logical': 10, 'disk': {'/': {'total': 460.4317207336426, 'used': 12.228080749511719}}, 'gpuapple': {'type': 'arm', 'vendor': 'Apple'}, 'memory': {'total': 16.0}}
2024-01-21 06:11:54,040 INFO    HandlerThread:19058 [system_monitor.py:probe():224] Finished collecting system info
2024-01-21 06:11:54,040 INFO    HandlerThread:19058 [system_monitor.py:probe():227] Publishing system info
2024-01-21 06:11:54,040 DEBUG   HandlerThread:19058 [system_info.py:_save_conda():208] Saving list of conda packages installed into the current environment
2024-01-21 06:11:54,973 INFO    Thread-12 :19058 [dir_watcher.py:_on_file_created():271] file/dir created: /Users/suhuangyuan/DRA/wandb/run-20240121_061147-b1xmukc9/files/conda-environment.yaml
2024-01-21 06:11:55,423 DEBUG   HandlerThread:19058 [system_info.py:_save_conda():220] Saving conda packages done
2024-01-21 06:11:55,423 DEBUG   HandlerThread:19058 [system_info.py:_save_code():45] Saving code
2024-01-21 06:11:55,437 DEBUG   HandlerThread:19058 [system_info.py:_save_code():66] Saving code done
2024-01-21 06:11:55,437 DEBUG   HandlerThread:19058 [system_info.py:_save_patches():83] Saving git patches
2024-01-21 06:11:55,641 DEBUG   HandlerThread:19058 [system_info.py:_save_patches():125] Saving git patches done
2024-01-21 06:11:55,642 INFO    HandlerThread:19058 [system_monitor.py:probe():229] Finished publishing system info
2024-01-21 06:11:55,644 DEBUG   SenderThread:19058 [sender.py:send():382] send: files
2024-01-21 06:11:55,644 INFO    SenderThread:19058 [sender.py:_save_file():1403] saving file wandb-metadata.json with policy now
2024-01-21 06:11:55,644 INFO    SenderThread:19058 [sender.py:_save_file():1403] saving file code/main.py with policy now
2024-01-21 06:11:55,645 INFO    SenderThread:19058 [sender.py:_save_file():1403] saving file diff.patch with policy now
2024-01-21 06:11:55,647 DEBUG   HandlerThread:19058 [handler.py:handle_request():146] handle_request: python_packages
2024-01-21 06:11:55,648 DEBUG   HandlerThread:19058 [handler.py:handle_request():146] handle_request: stop_status
2024-01-21 06:11:55,648 DEBUG   SenderThread:19058 [sender.py:send_request():409] send_request: python_packages
2024-01-21 06:11:55,650 DEBUG   SenderThread:19058 [sender.py:send_request():409] send_request: stop_status
2024-01-21 06:11:55,651 DEBUG   HandlerThread:19058 [handler.py:handle_request():146] handle_request: internal_messages
2024-01-21 06:11:55,977 INFO    Thread-12 :19058 [dir_watcher.py:_on_file_modified():288] file/dir modified: /Users/suhuangyuan/DRA/wandb/run-20240121_061147-b1xmukc9/files/conda-environment.yaml
2024-01-21 06:11:55,977 INFO    Thread-12 :19058 [dir_watcher.py:_on_file_created():271] file/dir created: /Users/suhuangyuan/DRA/wandb/run-20240121_061147-b1xmukc9/files/diff.patch
2024-01-21 06:11:55,977 INFO    Thread-12 :19058 [dir_watcher.py:_on_file_created():271] file/dir created: /Users/suhuangyuan/DRA/wandb/run-20240121_061147-b1xmukc9/files/code/main.py
2024-01-21 06:11:55,977 INFO    Thread-12 :19058 [dir_watcher.py:_on_file_created():271] file/dir created: /Users/suhuangyuan/DRA/wandb/run-20240121_061147-b1xmukc9/files/wandb-metadata.json
2024-01-21 06:11:55,978 INFO    Thread-12 :19058 [dir_watcher.py:_on_file_created():271] file/dir created: /Users/suhuangyuan/DRA/wandb/run-20240121_061147-b1xmukc9/files/requirements.txt
2024-01-21 06:11:55,978 INFO    Thread-12 :19058 [dir_watcher.py:_on_file_created():271] file/dir created: /Users/suhuangyuan/DRA/wandb/run-20240121_061147-b1xmukc9/files/code
2024-01-21 06:11:57,995 DEBUG   HandlerThread:19058 [handler.py:handle_request():146] handle_request: partial_history
2024-01-21 06:11:57,995 DEBUG   HandlerThread:19058 [handler.py:handle_request():146] handle_request: partial_history
2024-01-21 06:11:57,996 DEBUG   HandlerThread:19058 [handler.py:handle_request():146] handle_request: partial_history
2024-01-21 06:11:57,996 DEBUG   HandlerThread:19058 [handler.py:handle_request():146] handle_request: partial_history
2024-01-21 06:11:57,996 DEBUG   HandlerThread:19058 [handler.py:handle_request():146] handle_request: partial_history
2024-01-21 06:11:57,996 DEBUG   HandlerThread:19058 [handler.py:handle_request():146] handle_request: partial_history
2024-01-21 06:11:58,288 DEBUG   SenderThread:19058 [sender.py:send():382] send: telemetry
2024-01-21 06:11:58,989 INFO    Thread-12 :19058 [dir_watcher.py:_on_file_created():271] file/dir created: /Users/suhuangyuan/DRA/wandb/run-20240121_061147-b1xmukc9/files/output.log
2024-01-21 06:11:59,300 DEBUG   HandlerThread:19058 [handler.py:handle_request():146] handle_request: status_report
2024-01-21 06:11:59,600 INFO    wandb-upload_0:19058 [upload_job.py:push():131] Uploaded file /var/folders/72/mvwhplb93ms91mvl36q329qh0000gn/T/tmps00gbdphwandb/7k0d98rm-wandb-metadata.json
2024-01-21 06:12:01,000 INFO    Thread-12 :19058 [dir_watcher.py:_on_file_modified():288] file/dir modified: /Users/suhuangyuan/DRA/wandb/run-20240121_061147-b1xmukc9/files/output.log
2024-01-21 06:12:01,646 INFO    wandb-upload_1:19058 [upload_job.py:push():131] Uploaded file /var/folders/72/mvwhplb93ms91mvl36q329qh0000gn/T/tmps00gbdphwandb/7vcmzenu-code/main.py
2024-01-21 06:12:02,250 INFO    wandb-upload_2:19058 [upload_job.py:push():131] Uploaded file /var/folders/72/mvwhplb93ms91mvl36q329qh0000gn/T/tmps00gbdphwandb/0ac6l40k-diff.patch
2024-01-21 06:12:03,131 DEBUG   HandlerThread:19058 [handler.py:handle_request():146] handle_request: partial_history
2024-01-21 06:12:03,132 DEBUG   HandlerThread:19058 [handler.py:handle_request():146] handle_request: partial_history
2024-01-21 06:12:03,132 DEBUG   HandlerThread:19058 [handler.py:handle_request():146] handle_request: partial_history
2024-01-21 06:12:03,132 DEBUG   HandlerThread:19058 [handler.py:handle_request():146] handle_request: partial_history
2024-01-21 06:12:03,132 DEBUG   HandlerThread:19058 [handler.py:handle_request():146] handle_request: partial_history
2024-01-21 06:12:03,132 DEBUG   HandlerThread:19058 [handler.py:handle_request():146] handle_request: partial_history
2024-01-21 06:12:03,132 DEBUG   SenderThread:19058 [sender.py:send():382] send: history
2024-01-21 06:12:03,133 DEBUG   SenderThread:19058 [sender.py:send_request():409] send_request: summary_record
2024-01-21 06:12:03,133 INFO    SenderThread:19058 [sender.py:_save_file():1403] saving file wandb-summary.json with policy end
2024-01-21 06:12:04,014 INFO    Thread-12 :19058 [dir_watcher.py:_on_file_created():271] file/dir created: /Users/suhuangyuan/DRA/wandb/run-20240121_061147-b1xmukc9/files/wandb-summary.json
2024-01-21 06:12:05,019 INFO    Thread-12 :19058 [dir_watcher.py:_on_file_modified():288] file/dir modified: /Users/suhuangyuan/DRA/wandb/run-20240121_061147-b1xmukc9/files/output.log
2024-01-21 06:12:05,144 DEBUG   HandlerThread:19058 [handler.py:handle_request():146] handle_request: status_report
2024-01-21 06:12:08,530 DEBUG   HandlerThread:19058 [handler.py:handle_request():146] handle_request: partial_history
2024-01-21 06:12:08,530 DEBUG   HandlerThread:19058 [handler.py:handle_request():146] handle_request: partial_history
2024-01-21 06:12:08,531 DEBUG   HandlerThread:19058 [handler.py:handle_request():146] handle_request: partial_history
2024-01-21 06:12:08,531 DEBUG   HandlerThread:19058 [handler.py:handle_request():146] handle_request: partial_history
2024-01-21 06:12:08,531 DEBUG   HandlerThread:19058 [handler.py:handle_request():146] handle_request: partial_history
2024-01-21 06:12:08,531 DEBUG   SenderThread:19058 [sender.py:send():382] send: history
2024-01-21 06:12:08,531 DEBUG   SenderThread:19058 [sender.py:send_request():409] send_request: summary_record
2024-01-21 06:12:08,531 DEBUG   HandlerThread:19058 [handler.py:handle_request():146] handle_request: partial_history
2024-01-21 06:12:08,532 INFO    SenderThread:19058 [sender.py:_save_file():1403] saving file wandb-summary.json with policy end
2024-01-21 06:12:09,032 INFO    Thread-12 :19058 [dir_watcher.py:_on_file_modified():288] file/dir modified: /Users/suhuangyuan/DRA/wandb/run-20240121_061147-b1xmukc9/files/wandb-summary.json
2024-01-21 06:12:10,544 DEBUG   HandlerThread:19058 [handler.py:handle_request():146] handle_request: status_report
2024-01-21 06:12:10,652 DEBUG   HandlerThread:19058 [handler.py:handle_request():146] handle_request: stop_status
2024-01-21 06:12:10,653 DEBUG   SenderThread:19058 [sender.py:send_request():409] send_request: stop_status
2024-01-21 06:12:10,654 DEBUG   HandlerThread:19058 [handler.py:handle_request():146] handle_request: internal_messages
2024-01-21 06:12:11,036 INFO    Thread-12 :19058 [dir_watcher.py:_on_file_modified():288] file/dir modified: /Users/suhuangyuan/DRA/wandb/run-20240121_061147-b1xmukc9/files/output.log
2024-01-21 06:12:12,627 DEBUG   HandlerThread:19058 [handler.py:handle_request():146] handle_request: poll_exit
2024-01-21 06:12:14,317 DEBUG   SenderThread:19058 [sender.py:send():382] send: exit
2024-01-21 06:12:14,317 INFO    SenderThread:19058 [sender.py:send_exit():589] handling exit code: 1
2024-01-21 06:12:14,318 INFO    SenderThread:19058 [sender.py:send_exit():591] handling runtime: 17
2024-01-21 06:12:14,322 INFO    SenderThread:19058 [sender.py:_save_file():1403] saving file wandb-summary.json with policy end
2024-01-21 06:12:14,323 INFO    SenderThread:19058 [sender.py:send_exit():597] send defer
2024-01-21 06:12:14,324 DEBUG   SenderThread:19058 [sender.py:send_request():409] send_request: poll_exit
2024-01-21 06:12:14,324 DEBUG   HandlerThread:19058 [handler.py:handle_request():146] handle_request: defer
2024-01-21 06:12:14,324 INFO    HandlerThread:19058 [handler.py:handle_request_defer():172] handle defer: 0
2024-01-21 06:12:14,325 DEBUG   SenderThread:19058 [sender.py:send_request():409] send_request: defer
2024-01-21 06:12:14,325 INFO    SenderThread:19058 [sender.py:send_request_defer():613] handle sender defer: 0
2024-01-21 06:12:14,325 INFO    SenderThread:19058 [sender.py:transition_state():617] send defer: 1
2024-01-21 06:12:14,326 DEBUG   HandlerThread:19058 [handler.py:handle_request():146] handle_request: defer
2024-01-21 06:12:14,326 INFO    HandlerThread:19058 [handler.py:handle_request_defer():172] handle defer: 1
2024-01-21 06:12:14,326 DEBUG   SenderThread:19058 [sender.py:send_request():409] send_request: defer
2024-01-21 06:12:14,326 INFO    SenderThread:19058 [sender.py:send_request_defer():613] handle sender defer: 1
2024-01-21 06:12:14,326 INFO    SenderThread:19058 [sender.py:transition_state():617] send defer: 2
2024-01-21 06:12:14,326 DEBUG   HandlerThread:19058 [handler.py:handle_request():146] handle_request: defer
2024-01-21 06:12:14,326 INFO    HandlerThread:19058 [handler.py:handle_request_defer():172] handle defer: 2
2024-01-21 06:12:14,326 INFO    HandlerThread:19058 [system_monitor.py:finish():203] Stopping system monitor
2024-01-21 06:12:14,326 INFO    HandlerThread:19058 [interfaces.py:finish():202] Joined cpu monitor
2024-01-21 06:12:14,327 DEBUG   SystemMonitor:19058 [system_monitor.py:_start():172] Starting system metrics aggregation loop
2024-01-21 06:12:14,327 INFO    HandlerThread:19058 [interfaces.py:finish():202] Joined disk monitor
2024-01-21 06:12:14,327 DEBUG   SystemMonitor:19058 [system_monitor.py:_start():179] Finished system metrics aggregation loop
2024-01-21 06:12:14,327 INFO    HandlerThread:19058 [interfaces.py:finish():202] Joined gpuapple monitor
2024-01-21 06:12:14,327 DEBUG   SystemMonitor:19058 [system_monitor.py:_start():183] Publishing last batch of metrics
2024-01-21 06:12:14,327 INFO    HandlerThread:19058 [interfaces.py:finish():202] Joined memory monitor
2024-01-21 06:12:14,328 INFO    HandlerThread:19058 [interfaces.py:finish():202] Joined network monitor
2024-01-21 06:12:14,328 DEBUG   SenderThread:19058 [sender.py:send_request():409] send_request: defer
2024-01-21 06:12:14,328 INFO    SenderThread:19058 [sender.py:send_request_defer():613] handle sender defer: 2
2024-01-21 06:12:14,328 INFO    SenderThread:19058 [sender.py:transition_state():617] send defer: 3
2024-01-21 06:12:14,328 DEBUG   SenderThread:19058 [sender.py:send():382] send: telemetry
2024-01-21 06:12:14,329 DEBUG   SenderThread:19058 [sender.py:send():382] send: stats
2024-01-21 06:12:14,329 DEBUG   HandlerThread:19058 [handler.py:handle_request():146] handle_request: defer
2024-01-21 06:12:14,329 INFO    HandlerThread:19058 [handler.py:handle_request_defer():172] handle defer: 3
2024-01-21 06:12:14,330 DEBUG   SenderThread:19058 [sender.py:send():382] send: history
2024-01-21 06:12:14,330 DEBUG   SenderThread:19058 [sender.py:send_request():409] send_request: summary_record
2024-01-21 06:12:14,330 INFO    SenderThread:19058 [sender.py:_save_file():1403] saving file wandb-summary.json with policy end
2024-01-21 06:12:14,331 DEBUG   SenderThread:19058 [sender.py:send_request():409] send_request: defer
2024-01-21 06:12:14,331 INFO    SenderThread:19058 [sender.py:send_request_defer():613] handle sender defer: 3
2024-01-21 06:12:14,331 INFO    SenderThread:19058 [sender.py:transition_state():617] send defer: 4
2024-01-21 06:12:14,331 DEBUG   HandlerThread:19058 [handler.py:handle_request():146] handle_request: defer
2024-01-21 06:12:14,331 INFO    HandlerThread:19058 [handler.py:handle_request_defer():172] handle defer: 4
2024-01-21 06:12:14,331 DEBUG   SenderThread:19058 [sender.py:send_request():409] send_request: defer
2024-01-21 06:12:14,331 INFO    SenderThread:19058 [sender.py:send_request_defer():613] handle sender defer: 4
2024-01-21 06:12:14,331 INFO    SenderThread:19058 [sender.py:transition_state():617] send defer: 5
2024-01-21 06:12:14,331 DEBUG   HandlerThread:19058 [handler.py:handle_request():146] handle_request: defer
2024-01-21 06:12:14,331 INFO    HandlerThread:19058 [handler.py:handle_request_defer():172] handle defer: 5
2024-01-21 06:12:14,331 DEBUG   SenderThread:19058 [sender.py:send():382] send: summary
2024-01-21 06:12:14,332 INFO    SenderThread:19058 [sender.py:_save_file():1403] saving file wandb-summary.json with policy end
2024-01-21 06:12:14,332 DEBUG   SenderThread:19058 [sender.py:send_request():409] send_request: defer
2024-01-21 06:12:14,332 INFO    SenderThread:19058 [sender.py:send_request_defer():613] handle sender defer: 5
2024-01-21 06:12:14,332 INFO    SenderThread:19058 [sender.py:transition_state():617] send defer: 6
2024-01-21 06:12:14,332 DEBUG   HandlerThread:19058 [handler.py:handle_request():146] handle_request: defer
2024-01-21 06:12:14,332 INFO    HandlerThread:19058 [handler.py:handle_request_defer():172] handle defer: 6
2024-01-21 06:12:14,332 DEBUG   SenderThread:19058 [sender.py:send_request():409] send_request: defer
2024-01-21 06:12:14,332 INFO    SenderThread:19058 [sender.py:send_request_defer():613] handle sender defer: 6
2024-01-21 06:12:14,335 DEBUG   HandlerThread:19058 [handler.py:handle_request():146] handle_request: status_report
2024-01-21 06:12:14,637 DEBUG   HandlerThread:19058 [handler.py:handle_request():146] handle_request: poll_exit
2024-01-21 06:12:15,058 INFO    Thread-12 :19058 [dir_watcher.py:_on_file_modified():288] file/dir modified: /Users/suhuangyuan/DRA/wandb/run-20240121_061147-b1xmukc9/files/wandb-summary.json
2024-01-21 06:12:17,068 INFO    Thread-12 :19058 [dir_watcher.py:_on_file_modified():288] file/dir modified: /Users/suhuangyuan/DRA/wandb/run-20240121_061147-b1xmukc9/files/output.log
2024-01-21 06:12:19,658 DEBUG   HandlerThread:19058 [handler.py:handle_request():146] handle_request: keepalive
2024-01-21 06:12:20,780 WARNING StreamThr :19058 [internal.py:is_dead():414] Internal process exiting, parent pid 19025 disappeared
2024-01-21 06:12:20,780 ERROR   StreamThr :19058 [internal.py:wandb_internal():152] Internal process shutdown.
2024-01-21 06:12:21,667 INFO    WriterThread:19058 [datastore.py:close():296] close: /Users/suhuangyuan/DRA/wandb/run-20240121_061147-b1xmukc9/run-b1xmukc9.wandb
2024-01-21 06:12:21,667 INFO    HandlerThread:19058 [handler.py:finish():869] shutting down handler
2024-01-21 06:12:36,111 INFO    SenderThread:19058 [sender.py:transition_state():617] send defer: 7
2024-01-21 06:12:36,111 INFO    SenderThread:19058 [sender.py:finish():1572] shutting down sender
2024-01-21 06:12:36,157 INFO    Thread-12 :19058 [dir_watcher.py:_on_file_modified():288] file/dir modified: /Users/suhuangyuan/DRA/wandb/run-20240121_061147-b1xmukc9/files/config.yaml
2024-01-21 06:12:38,378 INFO    SenderThread:19058 [dir_watcher.py:finish():358] shutting down directory watcher
2024-01-21 06:12:39,165 INFO    Thread-12 :19058 [dir_watcher.py:_on_file_modified():288] file/dir modified: /Users/suhuangyuan/DRA/wandb/run-20240121_061147-b1xmukc9/files/output.log
2024-01-21 06:12:39,166 INFO    SenderThread:19058 [dir_watcher.py:finish():388] scan: /Users/suhuangyuan/DRA/wandb/run-20240121_061147-b1xmukc9/files
2024-01-21 06:12:39,166 INFO    SenderThread:19058 [dir_watcher.py:finish():402] scan save: /Users/suhuangyuan/DRA/wandb/run-20240121_061147-b1xmukc9/files/diff.patch diff.patch
2024-01-21 06:12:39,166 INFO    SenderThread:19058 [dir_watcher.py:finish():402] scan save: /Users/suhuangyuan/DRA/wandb/run-20240121_061147-b1xmukc9/files/requirements.txt requirements.txt
2024-01-21 06:12:39,166 INFO    SenderThread:19058 [dir_watcher.py:finish():402] scan save: /Users/suhuangyuan/DRA/wandb/run-20240121_061147-b1xmukc9/files/output.log output.log
2024-01-21 06:12:39,169 INFO    SenderThread:19058 [dir_watcher.py:finish():402] scan save: /Users/suhuangyuan/DRA/wandb/run-20240121_061147-b1xmukc9/files/config.yaml config.yaml
2024-01-21 06:12:39,170 INFO    SenderThread:19058 [dir_watcher.py:finish():402] scan save: /Users/suhuangyuan/DRA/wandb/run-20240121_061147-b1xmukc9/files/wandb-summary.json wandb-summary.json
2024-01-21 06:12:39,170 INFO    SenderThread:19058 [dir_watcher.py:finish():402] scan save: /Users/suhuangyuan/DRA/wandb/run-20240121_061147-b1xmukc9/files/conda-environment.yaml conda-environment.yaml
2024-01-21 06:12:39,177 INFO    SenderThread:19058 [dir_watcher.py:finish():402] scan save: /Users/suhuangyuan/DRA/wandb/run-20240121_061147-b1xmukc9/files/wandb-metadata.json wandb-metadata.json
2024-01-21 06:12:39,190 INFO    SenderThread:19058 [dir_watcher.py:finish():402] scan save: /Users/suhuangyuan/DRA/wandb/run-20240121_061147-b1xmukc9/files/code/main.py code/main.py
2024-01-21 06:12:39,190 INFO    SenderThread:19058 [file_pusher.py:finish():175] shutting down file pusher
2024-01-21 06:12:39,190 INFO    SenderThread:19058 [file_pusher.py:join():181] waiting for file pusher
2024-01-21 06:12:59,192 INFO    wandb-upload_2:19058 [retry.py:__call__():172] Retry attempt failed:
Traceback (most recent call last):
  File "/Users/suhuangyuan/miniconda3/envs/resource/lib/python3.9/site-packages/urllib3/connectionpool.py", line 536, in _make_request
    response = conn.getresponse()
  File "/Users/suhuangyuan/miniconda3/envs/resource/lib/python3.9/site-packages/urllib3/connection.py", line 461, in getresponse
    httplib_response = super().getresponse()
  File "/Users/suhuangyuan/miniconda3/envs/resource/lib/python3.9/http/client.py", line 1377, in getresponse
    response.begin()
  File "/Users/suhuangyuan/miniconda3/envs/resource/lib/python3.9/http/client.py", line 320, in begin
    version, status, reason = self._read_status()
  File "/Users/suhuangyuan/miniconda3/envs/resource/lib/python3.9/http/client.py", line 281, in _read_status
    line = str(self.fp.readline(_MAXLINE + 1), "iso-8859-1")
  File "/Users/suhuangyuan/miniconda3/envs/resource/lib/python3.9/socket.py", line 704, in readinto
    return self._sock.recv_into(b)
  File "/Users/suhuangyuan/miniconda3/envs/resource/lib/python3.9/ssl.py", line 1275, in recv_into
    return self.read(nbytes, buffer)
  File "/Users/suhuangyuan/miniconda3/envs/resource/lib/python3.9/ssl.py", line 1133, in read
    return self._sslobj.read(len, buffer)
socket.timeout: The read operation timed out

The above exception was the direct cause of the following exception:

Traceback (most recent call last):
  File "/Users/suhuangyuan/miniconda3/envs/resource/lib/python3.9/site-packages/requests/adapters.py", line 486, in send
    resp = conn.urlopen(
  File "/Users/suhuangyuan/miniconda3/envs/resource/lib/python3.9/site-packages/urllib3/connectionpool.py", line 844, in urlopen
    retries = retries.increment(
  File "/Users/suhuangyuan/miniconda3/envs/resource/lib/python3.9/site-packages/urllib3/util/retry.py", line 470, in increment
    raise reraise(type(error), error, _stacktrace)
  File "/Users/suhuangyuan/miniconda3/envs/resource/lib/python3.9/site-packages/urllib3/util/util.py", line 39, in reraise
    raise value
  File "/Users/suhuangyuan/miniconda3/envs/resource/lib/python3.9/site-packages/urllib3/connectionpool.py", line 790, in urlopen
    response = self._make_request(
  File "/Users/suhuangyuan/miniconda3/envs/resource/lib/python3.9/site-packages/urllib3/connectionpool.py", line 538, in _make_request
    self._raise_timeout(err=e, url=url, timeout_value=read_timeout)
  File "/Users/suhuangyuan/miniconda3/envs/resource/lib/python3.9/site-packages/urllib3/connectionpool.py", line 370, in _raise_timeout
    raise ReadTimeoutError(
urllib3.exceptions.ReadTimeoutError: HTTPSConnectionPool(host='api.wandb.ai', port=443): Read timed out. (read timeout=20)

During handling of the above exception, another exception occurred:

Traceback (most recent call last):
  File "/Users/suhuangyuan/miniconda3/envs/resource/lib/python3.9/site-packages/wandb/sdk/lib/retry.py", line 131, in __call__
    result = self._call_fn(*args, **kwargs)
  File "/Users/suhuangyuan/miniconda3/envs/resource/lib/python3.9/site-packages/wandb/sdk/internal/internal_api.py", line 369, in execute
    return self.client.execute(*args, **kwargs)  # type: ignore
  File "/Users/suhuangyuan/miniconda3/envs/resource/lib/python3.9/site-packages/wandb/vendor/gql-0.2.0/wandb_gql/client.py", line 52, in execute
    result = self._get_result(document, *args, **kwargs)
  File "/Users/suhuangyuan/miniconda3/envs/resource/lib/python3.9/site-packages/wandb/vendor/gql-0.2.0/wandb_gql/client.py", line 60, in _get_result
    return self.transport.execute(document, *args, **kwargs)
  File "/Users/suhuangyuan/miniconda3/envs/resource/lib/python3.9/site-packages/wandb/sdk/lib/gql_request.py", line 58, in execute
    request = self.session.post(self.url, **post_args)
  File "/Users/suhuangyuan/miniconda3/envs/resource/lib/python3.9/site-packages/requests/sessions.py", line 637, in post
    return self.request("POST", url, data=data, json=json, **kwargs)
  File "/Users/suhuangyuan/miniconda3/envs/resource/lib/python3.9/site-packages/requests/sessions.py", line 589, in request
    resp = self.send(prep, **send_kwargs)
  File "/Users/suhuangyuan/miniconda3/envs/resource/lib/python3.9/site-packages/requests/sessions.py", line 703, in send
    r = adapter.send(request, **kwargs)
  File "/Users/suhuangyuan/miniconda3/envs/resource/lib/python3.9/site-packages/requests/adapters.py", line 532, in send
    raise ReadTimeout(e, request=request)
requests.exceptions.ReadTimeout: HTTPSConnectionPool(host='api.wandb.ai', port=443): Read timed out. (read timeout=20)
2024-01-21 06:12:59,559 INFO    wandb-upload_3:19058 [upload_job.py:push():131] Uploaded file /Users/suhuangyuan/DRA/wandb/run-20240121_061147-b1xmukc9/files/output.log
2024-01-21 06:13:01,062 INFO    wandb-upload_2:19058 [upload_job.py:push():131] Uploaded file /Users/suhuangyuan/DRA/wandb/run-20240121_061147-b1xmukc9/files/wandb-summary.json
2024-01-21 06:13:33,420 ERROR   wandb-upload_0:19058 [internal_api.py:upload_file():2765] upload_file exception https://storage.googleapis.com/wandb-production.appspot.com/iris-tajwar/ToM2C/b1xmukc9/requirements.txt?Expires=1705875159&GoogleAccessId=gorilla-files-url-signer-man%40wandb-production.iam.gserviceaccount.com&Signature=OHgoAgIfp8fX6s1EHKsFoHNSbBkN7ZH3EYUtUqZjp6GADZDVcJm741G21vacOMOeRLjkZJjB4pra741Ie2Td5Q%2BiQR5Up7LReb3NezA%2F1ZG9SbJGnu554%2Fgm2KvEbH4g6tFVh991t3YrIJM6BC9UpiuDEppAjKj5dBp7fj%2BtKBKrgNZ52UsXfl1Om8SHosZKgx3x1gBMd3DEFxAfacBUoJgKtMfTb2Tx6ZS41L6LknIvmRjQ7RIQuy3f2MyU3dcPL4MTeY3lm3Sox4yIbk0fArri0tLuoR9ExK2lLYIhaNET5TsQ6MRTBetQxnY8e20mmAlp1UkNkHhvn9G9sXMfQQ%3D%3D: ('Connection aborted.', TimeoutError(60, 'Operation timed out'))
2024-01-21 06:13:33,420 ERROR   wandb-upload_0:19058 [internal_api.py:upload_file():2767] upload_file request headers: {'User-Agent': 'python-requests/2.31.0', 'Accept-Encoding': 'gzip, deflate', 'Accept': '*/*', 'Connection': 'keep-alive', 'Content-Length': '856'}
2024-01-21 06:13:33,420 ERROR   wandb-upload_0:19058 [internal_api.py:upload_file():2769] upload_file response body: 
2024-01-21 06:13:35,035 INFO    wandb-upload_0:19058 [upload_job.py:push():131] Uploaded file /Users/suhuangyuan/DRA/wandb/run-20240121_061147-b1xmukc9/files/requirements.txt
2024-01-21 06:14:21,045 ERROR   wandb-upload_4:19058 [internal_api.py:upload_file():2765] upload_file exception https://storage.googleapis.com/wandb-production.appspot.com/iris-tajwar/ToM2C/b1xmukc9/conda-environment.yaml?Expires=1705875159&GoogleAccessId=gorilla-files-url-signer-man%40wandb-production.iam.gserviceaccount.com&Signature=a0TAlc6x%2FrbgSIsqzB9Oc3Zpy2JPE5uC%2FvfpqLJBRPuBvCQskfPgO5%2BRnf6zeC%2FXRAV83Kml66V1m%2FbvP9BnozDPBuTvogdLzvUqx0xHGxc%2Baqjfcoti%2FUN2L5vsF3yGV5Bs5ghuVV2pi%2ByegEx%2BT5dH5m7zNMoGWA8fScIN2GGEV0gUt7rbc2BprJp7QT8xLzdwA2x5oMmO0cxojJ6MGoARO7XDvqycJTgRVxhvf3atvR%2BN7dlXTc3fa53P%2FpAXpE2PxRykTccPTpPYPnurwgU%2BG15meJR1bjkUaN1S4l2DlaWdD2dBiI78LnimOIbKzCvpFoBloFLaR39HMuL%2Fyw%3D%3D: ('Connection aborted.', TimeoutError(60, 'Operation timed out'))
2024-01-21 06:14:21,047 ERROR   wandb-upload_4:19058 [internal_api.py:upload_file():2767] upload_file request headers: {'User-Agent': 'python-requests/2.31.0', 'Accept-Encoding': 'gzip, deflate', 'Accept': '*/*', 'Connection': 'keep-alive', 'Content-Length': '2099'}
2024-01-21 06:14:21,047 ERROR   wandb-upload_4:19058 [internal_api.py:upload_file():2769] upload_file response body: 
2024-01-21 06:14:22,754 INFO    wandb-upload_4:19058 [upload_job.py:push():131] Uploaded file /Users/suhuangyuan/DRA/wandb/run-20240121_061147-b1xmukc9/files/conda-environment.yaml
2024-01-21 06:15:13,705 ERROR   wandb-upload_1:19058 [internal_api.py:upload_file():2765] upload_file exception https://storage.googleapis.com/wandb-production.appspot.com/iris-tajwar/ToM2C/b1xmukc9/config.yaml?Expires=1705875178&GoogleAccessId=gorilla-files-url-signer-man%40wandb-production.iam.gserviceaccount.com&Signature=O6lEv4Dw17WYoaDnx89o8Z17hcx7bVvaLY9T9DlxkIP5uwX6B5MMSRZ4YSWU0mE7b0H6gb0ZuTohXOrycsX0jbj6lyIMoISYFsxKFLQ9JQTlgqhRBfY1plSjsYoQmcgL9pcr2yV1PPfWp%2BZ7jUbOamptxnYyNviR4D8UxuTiIlESeOt4LzBYqyjb1RDHPksYH9WswU5xPDM085tcPmx1bnXi2o1UtrRf50DGEi3q%2FfeSj9dXQXr5hAyzZ2J5jaoY7ICowI4rqQA3bIad%2FUjIA0%2F0WwE5e4PcszBGAlYyuUP%2Bu8FvXF0vWjpwYoFT%2FbaBBJhjWQaBxyaRbzuovsAY6g%3D%3D: ('Connection aborted.', TimeoutError(60, 'Operation timed out'))
2024-01-21 06:15:13,707 ERROR   wandb-upload_1:19058 [internal_api.py:upload_file():2767] upload_file request headers: {'User-Agent': 'python-requests/2.31.0', 'Accept-Encoding': 'gzip, deflate', 'Accept': '*/*', 'Connection': 'keep-alive', 'Content-Length': '427'}
2024-01-21 06:15:13,707 ERROR   wandb-upload_1:19058 [internal_api.py:upload_file():2769] upload_file response body: 
2024-01-21 06:15:13,707 INFO    wandb-upload_1:19058 [retry.py:__call__():172] Retry attempt failed:
Traceback (most recent call last):
  File "/Users/suhuangyuan/miniconda3/envs/resource/lib/python3.9/site-packages/urllib3/connectionpool.py", line 790, in urlopen
    response = self._make_request(
  File "/Users/suhuangyuan/miniconda3/envs/resource/lib/python3.9/site-packages/urllib3/connectionpool.py", line 536, in _make_request
    response = conn.getresponse()
  File "/Users/suhuangyuan/miniconda3/envs/resource/lib/python3.9/site-packages/urllib3/connection.py", line 461, in getresponse
    httplib_response = super().getresponse()
  File "/Users/suhuangyuan/miniconda3/envs/resource/lib/python3.9/http/client.py", line 1377, in getresponse
    response.begin()
  File "/Users/suhuangyuan/miniconda3/envs/resource/lib/python3.9/http/client.py", line 320, in begin
    version, status, reason = self._read_status()
  File "/Users/suhuangyuan/miniconda3/envs/resource/lib/python3.9/http/client.py", line 281, in _read_status
    line = str(self.fp.readline(_MAXLINE + 1), "iso-8859-1")
  File "/Users/suhuangyuan/miniconda3/envs/resource/lib/python3.9/socket.py", line 704, in readinto
    return self._sock.recv_into(b)
  File "/Users/suhuangyuan/miniconda3/envs/resource/lib/python3.9/ssl.py", line 1275, in recv_into
    return self.read(nbytes, buffer)
  File "/Users/suhuangyuan/miniconda3/envs/resource/lib/python3.9/ssl.py", line 1133, in read
    return self._sslobj.read(len, buffer)
TimeoutError: [Errno 60] Operation timed out

During handling of the above exception, another exception occurred:

Traceback (most recent call last):
  File "/Users/suhuangyuan/miniconda3/envs/resource/lib/python3.9/site-packages/requests/adapters.py", line 486, in send
    resp = conn.urlopen(
  File "/Users/suhuangyuan/miniconda3/envs/resource/lib/python3.9/site-packages/urllib3/connectionpool.py", line 844, in urlopen
    retries = retries.increment(
  File "/Users/suhuangyuan/miniconda3/envs/resource/lib/python3.9/site-packages/urllib3/util/retry.py", line 470, in increment
    raise reraise(type(error), error, _stacktrace)
  File "/Users/suhuangyuan/miniconda3/envs/resource/lib/python3.9/site-packages/urllib3/util/util.py", line 38, in reraise
    raise value.with_traceback(tb)
  File "/Users/suhuangyuan/miniconda3/envs/resource/lib/python3.9/site-packages/urllib3/connectionpool.py", line 790, in urlopen
    response = self._make_request(
  File "/Users/suhuangyuan/miniconda3/envs/resource/lib/python3.9/site-packages/urllib3/connectionpool.py", line 536, in _make_request
    response = conn.getresponse()
  File "/Users/suhuangyuan/miniconda3/envs/resource/lib/python3.9/site-packages/urllib3/connection.py", line 461, in getresponse
    httplib_response = super().getresponse()
  File "/Users/suhuangyuan/miniconda3/envs/resource/lib/python3.9/http/client.py", line 1377, in getresponse
    response.begin()
  File "/Users/suhuangyuan/miniconda3/envs/resource/lib/python3.9/http/client.py", line 320, in begin
    version, status, reason = self._read_status()
  File "/Users/suhuangyuan/miniconda3/envs/resource/lib/python3.9/http/client.py", line 281, in _read_status
    line = str(self.fp.readline(_MAXLINE + 1), "iso-8859-1")
  File "/Users/suhuangyuan/miniconda3/envs/resource/lib/python3.9/socket.py", line 704, in readinto
    return self._sock.recv_into(b)
  File "/Users/suhuangyuan/miniconda3/envs/resource/lib/python3.9/ssl.py", line 1275, in recv_into
    return self.read(nbytes, buffer)
  File "/Users/suhuangyuan/miniconda3/envs/resource/lib/python3.9/ssl.py", line 1133, in read
    return self._sslobj.read(len, buffer)
urllib3.exceptions.ProtocolError: ('Connection aborted.', TimeoutError(60, 'Operation timed out'))

During handling of the above exception, another exception occurred:

Traceback (most recent call last):
  File "/Users/suhuangyuan/miniconda3/envs/resource/lib/python3.9/site-packages/wandb/sdk/internal/internal_api.py", line 2758, in upload_file
    response = self._upload_file_session.put(
  File "/Users/suhuangyuan/miniconda3/envs/resource/lib/python3.9/site-packages/requests/sessions.py", line 649, in put
    return self.request("PUT", url, data=data, **kwargs)
  File "/Users/suhuangyuan/miniconda3/envs/resource/lib/python3.9/site-packages/requests/sessions.py", line 589, in request
    resp = self.send(prep, **send_kwargs)
  File "/Users/suhuangyuan/miniconda3/envs/resource/lib/python3.9/site-packages/requests/sessions.py", line 703, in send
    r = adapter.send(request, **kwargs)
  File "/Users/suhuangyuan/miniconda3/envs/resource/lib/python3.9/site-packages/requests/adapters.py", line 501, in send
    raise ConnectionError(err, request=request)
requests.exceptions.ConnectionError: ('Connection aborted.', TimeoutError(60, 'Operation timed out'))

During handling of the above exception, another exception occurred:

Traceback (most recent call last):
  File "/Users/suhuangyuan/miniconda3/envs/resource/lib/python3.9/site-packages/wandb/sdk/lib/retry.py", line 131, in __call__
    result = self._call_fn(*args, **kwargs)
  File "/Users/suhuangyuan/miniconda3/envs/resource/lib/python3.9/site-packages/wandb/sdk/internal/internal_api.py", line 2789, in upload_file
    raise _e.with_traceback(sys.exc_info()[2])
  File "/Users/suhuangyuan/miniconda3/envs/resource/lib/python3.9/site-packages/wandb/sdk/internal/internal_api.py", line 2758, in upload_file
    response = self._upload_file_session.put(
  File "/Users/suhuangyuan/miniconda3/envs/resource/lib/python3.9/site-packages/requests/sessions.py", line 649, in put
    return self.request("PUT", url, data=data, **kwargs)
  File "/Users/suhuangyuan/miniconda3/envs/resource/lib/python3.9/site-packages/requests/sessions.py", line 589, in request
    resp = self.send(prep, **send_kwargs)
  File "/Users/suhuangyuan/miniconda3/envs/resource/lib/python3.9/site-packages/requests/sessions.py", line 703, in send
    r = adapter.send(request, **kwargs)
  File "/Users/suhuangyuan/miniconda3/envs/resource/lib/python3.9/site-packages/requests/adapters.py", line 501, in send
    raise ConnectionError(err, request=request)
wandb.sdk.lib.retry.TransientError: None
2024-01-21 06:15:13,708 ERROR   wandb-upload_1:19058 [upload_job.py:push():134] Failed to upload file: /Users/suhuangyuan/DRA/wandb/run-20240121_061147-b1xmukc9/files/config.yaml
Traceback (most recent call last):
  File "/Users/suhuangyuan/miniconda3/envs/resource/lib/python3.9/site-packages/urllib3/connectionpool.py", line 790, in urlopen
    response = self._make_request(
  File "/Users/suhuangyuan/miniconda3/envs/resource/lib/python3.9/site-packages/urllib3/connectionpool.py", line 536, in _make_request
    response = conn.getresponse()
  File "/Users/suhuangyuan/miniconda3/envs/resource/lib/python3.9/site-packages/urllib3/connection.py", line 461, in getresponse
    httplib_response = super().getresponse()
  File "/Users/suhuangyuan/miniconda3/envs/resource/lib/python3.9/http/client.py", line 1377, in getresponse
    response.begin()
  File "/Users/suhuangyuan/miniconda3/envs/resource/lib/python3.9/http/client.py", line 320, in begin
    version, status, reason = self._read_status()
  File "/Users/suhuangyuan/miniconda3/envs/resource/lib/python3.9/http/client.py", line 281, in _read_status
    line = str(self.fp.readline(_MAXLINE + 1), "iso-8859-1")
  File "/Users/suhuangyuan/miniconda3/envs/resource/lib/python3.9/socket.py", line 704, in readinto
    return self._sock.recv_into(b)
  File "/Users/suhuangyuan/miniconda3/envs/resource/lib/python3.9/ssl.py", line 1275, in recv_into
    return self.read(nbytes, buffer)
  File "/Users/suhuangyuan/miniconda3/envs/resource/lib/python3.9/ssl.py", line 1133, in read
    return self._sslobj.read(len, buffer)
TimeoutError: [Errno 60] Operation timed out

During handling of the above exception, another exception occurred:

Traceback (most recent call last):
  File "/Users/suhuangyuan/miniconda3/envs/resource/lib/python3.9/site-packages/requests/adapters.py", line 486, in send
    resp = conn.urlopen(
  File "/Users/suhuangyuan/miniconda3/envs/resource/lib/python3.9/site-packages/urllib3/connectionpool.py", line 844, in urlopen
    retries = retries.increment(
  File "/Users/suhuangyuan/miniconda3/envs/resource/lib/python3.9/site-packages/urllib3/util/retry.py", line 470, in increment
    raise reraise(type(error), error, _stacktrace)
  File "/Users/suhuangyuan/miniconda3/envs/resource/lib/python3.9/site-packages/urllib3/util/util.py", line 38, in reraise
    raise value.with_traceback(tb)
  File "/Users/suhuangyuan/miniconda3/envs/resource/lib/python3.9/site-packages/urllib3/connectionpool.py", line 790, in urlopen
    response = self._make_request(
  File "/Users/suhuangyuan/miniconda3/envs/resource/lib/python3.9/site-packages/urllib3/connectionpool.py", line 536, in _make_request
    response = conn.getresponse()
  File "/Users/suhuangyuan/miniconda3/envs/resource/lib/python3.9/site-packages/urllib3/connection.py", line 461, in getresponse
    httplib_response = super().getresponse()
  File "/Users/suhuangyuan/miniconda3/envs/resource/lib/python3.9/http/client.py", line 1377, in getresponse
    response.begin()
  File "/Users/suhuangyuan/miniconda3/envs/resource/lib/python3.9/http/client.py", line 320, in begin
    version, status, reason = self._read_status()
  File "/Users/suhuangyuan/miniconda3/envs/resource/lib/python3.9/http/client.py", line 281, in _read_status
    line = str(self.fp.readline(_MAXLINE + 1), "iso-8859-1")
  File "/Users/suhuangyuan/miniconda3/envs/resource/lib/python3.9/socket.py", line 704, in readinto
    return self._sock.recv_into(b)
  File "/Users/suhuangyuan/miniconda3/envs/resource/lib/python3.9/ssl.py", line 1275, in recv_into
    return self.read(nbytes, buffer)
  File "/Users/suhuangyuan/miniconda3/envs/resource/lib/python3.9/ssl.py", line 1133, in read
    return self._sslobj.read(len, buffer)
urllib3.exceptions.ProtocolError: ('Connection aborted.', TimeoutError(60, 'Operation timed out'))

During handling of the above exception, another exception occurred:

Traceback (most recent call last):
  File "/Users/suhuangyuan/miniconda3/envs/resource/lib/python3.9/site-packages/wandb/sdk/internal/internal_api.py", line 2758, in upload_file
    response = self._upload_file_session.put(
  File "/Users/suhuangyuan/miniconda3/envs/resource/lib/python3.9/site-packages/requests/sessions.py", line 649, in put
    return self.request("PUT", url, data=data, **kwargs)
  File "/Users/suhuangyuan/miniconda3/envs/resource/lib/python3.9/site-packages/requests/sessions.py", line 589, in request
    resp = self.send(prep, **send_kwargs)
  File "/Users/suhuangyuan/miniconda3/envs/resource/lib/python3.9/site-packages/requests/sessions.py", line 703, in send
    r = adapter.send(request, **kwargs)
  File "/Users/suhuangyuan/miniconda3/envs/resource/lib/python3.9/site-packages/requests/adapters.py", line 501, in send
    raise ConnectionError(err, request=request)
requests.exceptions.ConnectionError: ('Connection aborted.', TimeoutError(60, 'Operation timed out'))

During handling of the above exception, another exception occurred:

Traceback (most recent call last):
  File "/Users/suhuangyuan/miniconda3/envs/resource/lib/python3.9/site-packages/wandb/sdk/lib/retry.py", line 131, in __call__
    result = self._call_fn(*args, **kwargs)
  File "/Users/suhuangyuan/miniconda3/envs/resource/lib/python3.9/site-packages/wandb/sdk/internal/internal_api.py", line 2789, in upload_file
    raise _e.with_traceback(sys.exc_info()[2])
  File "/Users/suhuangyuan/miniconda3/envs/resource/lib/python3.9/site-packages/wandb/sdk/internal/internal_api.py", line 2758, in upload_file
    response = self._upload_file_session.put(
  File "/Users/suhuangyuan/miniconda3/envs/resource/lib/python3.9/site-packages/requests/sessions.py", line 649, in put
    return self.request("PUT", url, data=data, **kwargs)
  File "/Users/suhuangyuan/miniconda3/envs/resource/lib/python3.9/site-packages/requests/sessions.py", line 589, in request
    resp = self.send(prep, **send_kwargs)
  File "/Users/suhuangyuan/miniconda3/envs/resource/lib/python3.9/site-packages/requests/sessions.py", line 703, in send
    r = adapter.send(request, **kwargs)
  File "/Users/suhuangyuan/miniconda3/envs/resource/lib/python3.9/site-packages/requests/adapters.py", line 501, in send
    raise ConnectionError(err, request=request)
wandb.sdk.lib.retry.TransientError: None

During handling of the above exception, another exception occurred:

Traceback (most recent call last):
  File "/Users/suhuangyuan/miniconda3/envs/resource/lib/python3.9/site-packages/wandb/apis/normalize.py", line 41, in wrapper
    return func(*args, **kwargs)
  File "/Users/suhuangyuan/miniconda3/envs/resource/lib/python3.9/site-packages/wandb/sdk/lib/retry.py", line 212, in wrapped_fn
    return retrier(*args, **kargs)
  File "/Users/suhuangyuan/miniconda3/envs/resource/lib/python3.9/site-packages/wandb/sdk/lib/retry.py", line 183, in __call__
    wandb.termlog(
  File "/Users/suhuangyuan/miniconda3/envs/resource/lib/python3.9/site-packages/wandb/errors/term.py", line 39, in termlog
    _log(
  File "/Users/suhuangyuan/miniconda3/envs/resource/lib/python3.9/site-packages/wandb/errors/term.py", line 95, in _log
    click.echo(line, file=sys.stderr, nl=newline)
  File "/Users/suhuangyuan/miniconda3/envs/resource/lib/python3.9/site-packages/click/utils.py", line 318, in echo
    file.write(out)  # type: ignore
OSError: [Errno 5] Input/output error

During handling of the above exception, another exception occurred:

Traceback (most recent call last):
  File "/Users/suhuangyuan/miniconda3/envs/resource/lib/python3.9/site-packages/wandb/filesync/upload_job.py", line 125, in push
    self._api.upload_file_retry(
  File "/Users/suhuangyuan/miniconda3/envs/resource/lib/python3.9/site-packages/wandb/apis/normalize.py", line 87, in wrapper
    raise CommError(message, err).with_traceback(sys.exc_info()[2])
  File "/Users/suhuangyuan/miniconda3/envs/resource/lib/python3.9/site-packages/wandb/apis/normalize.py", line 41, in wrapper
    return func(*args, **kwargs)
  File "/Users/suhuangyuan/miniconda3/envs/resource/lib/python3.9/site-packages/wandb/sdk/lib/retry.py", line 212, in wrapped_fn
    return retrier(*args, **kargs)
  File "/Users/suhuangyuan/miniconda3/envs/resource/lib/python3.9/site-packages/wandb/sdk/lib/retry.py", line 183, in __call__
    wandb.termlog(
  File "/Users/suhuangyuan/miniconda3/envs/resource/lib/python3.9/site-packages/wandb/errors/term.py", line 39, in termlog
    _log(
  File "/Users/suhuangyuan/miniconda3/envs/resource/lib/python3.9/site-packages/wandb/errors/term.py", line 95, in _log
    click.echo(line, file=sys.stderr, nl=newline)
  File "/Users/suhuangyuan/miniconda3/envs/resource/lib/python3.9/site-packages/click/utils.py", line 318, in echo
    file.write(out)  # type: ignore
wandb.errors.CommError: [Errno 5] Input/output error
2024-01-21 06:15:14,330 WARNING FileStreamThread:19058 [file_stream.py:request_with_retry():668] requests_with_retry encountered retryable exception: HTTPSConnectionPool(host='api.wandb.ai', port=443): Read timed out. (read timeout=180). func: functools.partial(<bound method Session.post of <requests.sessions.Session object at 0x12d0b00d0>>, timeout=180), args: ('https://api.wandb.ai/files/iris-tajwar/ToM2C/b1xmukc9/file_stream',), kwargs: {'json': {'files': {'wandb-summary.json': {'offset': 0, 'content': ['{"train/policy_loss_sum": -2454.2138671875, "_timestamp": 1705788723.131105, "train/value_loss_sum": 263.4493713378906, "train/Sparsity_loss_sum": 8.451208114624023, "train/entropies_sum": 355.29888916015625, "train/gamma": 0.1, "train/action_correct_rate": 0.4444444477558136, "_runtime": 15.487644910812378, "_step": 240, "_wandb": {"runtime": 17}}']}}, 'dropped': 0}}
2024-01-21 06:15:15,744 ERROR   Thread-11 :19058 [step_upload.py:_handle_event():200] Failed to upload file: /Users/suhuangyuan/DRA/wandb/run-20240121_061147-b1xmukc9/files/config.yaml
Traceback (most recent call last):
  File "/Users/suhuangyuan/miniconda3/envs/resource/lib/python3.9/site-packages/urllib3/connectionpool.py", line 790, in urlopen
    response = self._make_request(
  File "/Users/suhuangyuan/miniconda3/envs/resource/lib/python3.9/site-packages/urllib3/connectionpool.py", line 536, in _make_request
    response = conn.getresponse()
  File "/Users/suhuangyuan/miniconda3/envs/resource/lib/python3.9/site-packages/urllib3/connection.py", line 461, in getresponse
    httplib_response = super().getresponse()
  File "/Users/suhuangyuan/miniconda3/envs/resource/lib/python3.9/http/client.py", line 1377, in getresponse
    response.begin()
  File "/Users/suhuangyuan/miniconda3/envs/resource/lib/python3.9/http/client.py", line 320, in begin
    version, status, reason = self._read_status()
  File "/Users/suhuangyuan/miniconda3/envs/resource/lib/python3.9/http/client.py", line 281, in _read_status
    line = str(self.fp.readline(_MAXLINE + 1), "iso-8859-1")
  File "/Users/suhuangyuan/miniconda3/envs/resource/lib/python3.9/socket.py", line 704, in readinto
    return self._sock.recv_into(b)
  File "/Users/suhuangyuan/miniconda3/envs/resource/lib/python3.9/ssl.py", line 1275, in recv_into
    return self.read(nbytes, buffer)
  File "/Users/suhuangyuan/miniconda3/envs/resource/lib/python3.9/ssl.py", line 1133, in read
    return self._sslobj.read(len, buffer)
TimeoutError: [Errno 60] Operation timed out

During handling of the above exception, another exception occurred:

Traceback (most recent call last):
  File "/Users/suhuangyuan/miniconda3/envs/resource/lib/python3.9/site-packages/requests/adapters.py", line 486, in send
    resp = conn.urlopen(
  File "/Users/suhuangyuan/miniconda3/envs/resource/lib/python3.9/site-packages/urllib3/connectionpool.py", line 844, in urlopen
    retries = retries.increment(
  File "/Users/suhuangyuan/miniconda3/envs/resource/lib/python3.9/site-packages/urllib3/util/retry.py", line 470, in increment
    raise reraise(type(error), error, _stacktrace)
  File "/Users/suhuangyuan/miniconda3/envs/resource/lib/python3.9/site-packages/urllib3/util/util.py", line 38, in reraise
    raise value.with_traceback(tb)
  File "/Users/suhuangyuan/miniconda3/envs/resource/lib/python3.9/site-packages/urllib3/connectionpool.py", line 790, in urlopen
    response = self._make_request(
  File "/Users/suhuangyuan/miniconda3/envs/resource/lib/python3.9/site-packages/urllib3/connectionpool.py", line 536, in _make_request
    response = conn.getresponse()
  File "/Users/suhuangyuan/miniconda3/envs/resource/lib/python3.9/site-packages/urllib3/connection.py", line 461, in getresponse
    httplib_response = super().getresponse()
  File "/Users/suhuangyuan/miniconda3/envs/resource/lib/python3.9/http/client.py", line 1377, in getresponse
    response.begin()
  File "/Users/suhuangyuan/miniconda3/envs/resource/lib/python3.9/http/client.py", line 320, in begin
    version, status, reason = self._read_status()
  File "/Users/suhuangyuan/miniconda3/envs/resource/lib/python3.9/http/client.py", line 281, in _read_status
    line = str(self.fp.readline(_MAXLINE + 1), "iso-8859-1")
  File "/Users/suhuangyuan/miniconda3/envs/resource/lib/python3.9/socket.py", line 704, in readinto
    return self._sock.recv_into(b)
  File "/Users/suhuangyuan/miniconda3/envs/resource/lib/python3.9/ssl.py", line 1275, in recv_into
    return self.read(nbytes, buffer)
  File "/Users/suhuangyuan/miniconda3/envs/resource/lib/python3.9/ssl.py", line 1133, in read
    return self._sslobj.read(len, buffer)
urllib3.exceptions.ProtocolError: ('Connection aborted.', TimeoutError(60, 'Operation timed out'))

During handling of the above exception, another exception occurred:

Traceback (most recent call last):
  File "/Users/suhuangyuan/miniconda3/envs/resource/lib/python3.9/site-packages/wandb/sdk/internal/internal_api.py", line 2758, in upload_file
    response = self._upload_file_session.put(
  File "/Users/suhuangyuan/miniconda3/envs/resource/lib/python3.9/site-packages/requests/sessions.py", line 649, in put
    return self.request("PUT", url, data=data, **kwargs)
  File "/Users/suhuangyuan/miniconda3/envs/resource/lib/python3.9/site-packages/requests/sessions.py", line 589, in request
    resp = self.send(prep, **send_kwargs)
  File "/Users/suhuangyuan/miniconda3/envs/resource/lib/python3.9/site-packages/requests/sessions.py", line 703, in send
    r = adapter.send(request, **kwargs)
  File "/Users/suhuangyuan/miniconda3/envs/resource/lib/python3.9/site-packages/requests/adapters.py", line 501, in send
    raise ConnectionError(err, request=request)
requests.exceptions.ConnectionError: ('Connection aborted.', TimeoutError(60, 'Operation timed out'))

During handling of the above exception, another exception occurred:

Traceback (most recent call last):
  File "/Users/suhuangyuan/miniconda3/envs/resource/lib/python3.9/site-packages/wandb/sdk/lib/retry.py", line 131, in __call__
    result = self._call_fn(*args, **kwargs)
  File "/Users/suhuangyuan/miniconda3/envs/resource/lib/python3.9/site-packages/wandb/sdk/internal/internal_api.py", line 2789, in upload_file
    raise _e.with_traceback(sys.exc_info()[2])
  File "/Users/suhuangyuan/miniconda3/envs/resource/lib/python3.9/site-packages/wandb/sdk/internal/internal_api.py", line 2758, in upload_file
    response = self._upload_file_session.put(
  File "/Users/suhuangyuan/miniconda3/envs/resource/lib/python3.9/site-packages/requests/sessions.py", line 649, in put
    return self.request("PUT", url, data=data, **kwargs)
  File "/Users/suhuangyuan/miniconda3/envs/resource/lib/python3.9/site-packages/requests/sessions.py", line 589, in request
    resp = self.send(prep, **send_kwargs)
  File "/Users/suhuangyuan/miniconda3/envs/resource/lib/python3.9/site-packages/requests/sessions.py", line 703, in send
    r = adapter.send(request, **kwargs)
  File "/Users/suhuangyuan/miniconda3/envs/resource/lib/python3.9/site-packages/requests/adapters.py", line 501, in send
    raise ConnectionError(err, request=request)
wandb.sdk.lib.retry.TransientError: None

During handling of the above exception, another exception occurred:

Traceback (most recent call last):
  File "/Users/suhuangyuan/miniconda3/envs/resource/lib/python3.9/site-packages/wandb/apis/normalize.py", line 41, in wrapper
    return func(*args, **kwargs)
  File "/Users/suhuangyuan/miniconda3/envs/resource/lib/python3.9/site-packages/wandb/sdk/lib/retry.py", line 212, in wrapped_fn
    return retrier(*args, **kargs)
  File "/Users/suhuangyuan/miniconda3/envs/resource/lib/python3.9/site-packages/wandb/sdk/lib/retry.py", line 183, in __call__
    wandb.termlog(
  File "/Users/suhuangyuan/miniconda3/envs/resource/lib/python3.9/site-packages/wandb/errors/term.py", line 39, in termlog
    _log(
  File "/Users/suhuangyuan/miniconda3/envs/resource/lib/python3.9/site-packages/wandb/errors/term.py", line 95, in _log
    click.echo(line, file=sys.stderr, nl=newline)
  File "/Users/suhuangyuan/miniconda3/envs/resource/lib/python3.9/site-packages/click/utils.py", line 318, in echo
    file.write(out)  # type: ignore
OSError: [Errno 5] Input/output error

During handling of the above exception, another exception occurred:

Traceback (most recent call last):
  File "/Users/suhuangyuan/miniconda3/envs/resource/lib/python3.9/site-packages/wandb/filesync/upload_job.py", line 125, in push
    self._api.upload_file_retry(
  File "/Users/suhuangyuan/miniconda3/envs/resource/lib/python3.9/site-packages/wandb/apis/normalize.py", line 87, in wrapper
    raise CommError(message, err).with_traceback(sys.exc_info()[2])
  File "/Users/suhuangyuan/miniconda3/envs/resource/lib/python3.9/site-packages/wandb/apis/normalize.py", line 41, in wrapper
    return func(*args, **kwargs)
  File "/Users/suhuangyuan/miniconda3/envs/resource/lib/python3.9/site-packages/wandb/sdk/lib/retry.py", line 212, in wrapped_fn
    return retrier(*args, **kargs)
  File "/Users/suhuangyuan/miniconda3/envs/resource/lib/python3.9/site-packages/wandb/sdk/lib/retry.py", line 183, in __call__
    wandb.termlog(
  File "/Users/suhuangyuan/miniconda3/envs/resource/lib/python3.9/site-packages/wandb/errors/term.py", line 39, in termlog
    _log(
  File "/Users/suhuangyuan/miniconda3/envs/resource/lib/python3.9/site-packages/wandb/errors/term.py", line 95, in _log
    click.echo(line, file=sys.stderr, nl=newline)
  File "/Users/suhuangyuan/miniconda3/envs/resource/lib/python3.9/site-packages/click/utils.py", line 318, in echo
    file.write(out)  # type: ignore
wandb.errors.CommError: [Errno 5] Input/output error

During handling of the above exception, another exception occurred:

Traceback (most recent call last):
  File "/Users/suhuangyuan/miniconda3/envs/resource/lib/python3.9/concurrent/futures/thread.py", line 58, in run
    result = self.fn(*self.args, **self.kwargs)
  File "/Users/suhuangyuan/miniconda3/envs/resource/lib/python3.9/site-packages/wandb/filesync/step_upload.py", line 288, in run_and_notify
    self._do_upload_sync(event)
  File "/Users/suhuangyuan/miniconda3/envs/resource/lib/python3.9/site-packages/wandb/filesync/step_upload.py", line 330, in _do_upload_sync
    job.run()
  File "/Users/suhuangyuan/miniconda3/envs/resource/lib/python3.9/site-packages/wandb/filesync/upload_job.py", line 57, in run
    self.push()
  File "/Users/suhuangyuan/miniconda3/envs/resource/lib/python3.9/site-packages/wandb/filesync/upload_job.py", line 137, in push
    wandb.termerror(
  File "/Users/suhuangyuan/miniconda3/envs/resource/lib/python3.9/site-packages/wandb/errors/term.py", line 61, in termerror
    _log(
  File "/Users/suhuangyuan/miniconda3/envs/resource/lib/python3.9/site-packages/wandb/errors/term.py", line 95, in _log
    click.echo(line, file=sys.stderr, nl=newline)
  File "/Users/suhuangyuan/miniconda3/envs/resource/lib/python3.9/site-packages/click/utils.py", line 318, in echo
    file.write(out)  # type: ignore
OSError: [Errno 5] Input/output error
2024-01-21 06:15:16,367 INFO    SenderThread:19058 [file_stream.py:finish():595] file stream finish called
2024-01-21 06:15:17,821 INFO    SenderThread:19058 [file_stream.py:finish():599] file stream finish is done
