2024-01-21 06:11:47,640 INFO    StreamThr :19057 [internal.py:wandb_internal():86] W&B internal server running at pid: 19057, started at: 2024-01-21 06:11:47.639817
2024-01-21 06:11:47,643 DEBUG   HandlerThread:19057 [handler.py:handle_request():146] handle_request: status
2024-01-21 06:11:47,647 INFO    WriterThread:19057 [datastore.py:open_for_write():87] open: /Users/suhuangyuan/DRA/wandb/run-20240121_061147-lvkhb8ha/run-lvkhb8ha.wandb
2024-01-21 06:11:47,647 DEBUG   SenderThread:19057 [sender.py:send():382] send: header
2024-01-21 06:11:47,673 DEBUG   SenderThread:19057 [sender.py:send():382] send: run
2024-01-21 06:11:51,048 INFO    SenderThread:19057 [dir_watcher.py:__init__():211] watching files in: /Users/suhuangyuan/DRA/wandb/run-20240121_061147-lvkhb8ha/files
2024-01-21 06:11:51,048 INFO    SenderThread:19057 [sender.py:_start_run_threads():1136] run started: lvkhb8ha with start time 1705788707.640107
2024-01-21 06:11:51,051 DEBUG   HandlerThread:19057 [handler.py:handle_request():146] handle_request: check_version
2024-01-21 06:11:51,051 DEBUG   SenderThread:19057 [sender.py:send_request():409] send_request: check_version
2024-01-21 06:11:54,112 DEBUG   HandlerThread:19057 [handler.py:handle_request():146] handle_request: status_report
2024-01-21 06:11:54,115 DEBUG   HandlerThread:19057 [handler.py:handle_request():146] handle_request: run_start
2024-01-21 06:11:54,122 DEBUG   HandlerThread:19057 [system_info.py:__init__():27] System info init
2024-01-21 06:11:54,123 DEBUG   HandlerThread:19057 [system_info.py:__init__():42] System info init done
2024-01-21 06:11:54,123 INFO    HandlerThread:19057 [system_monitor.py:start():194] Starting system monitor
2024-01-21 06:11:54,123 INFO    SystemMonitor:19057 [system_monitor.py:_start():158] Starting system asset monitoring threads
2024-01-21 06:11:54,123 INFO    HandlerThread:19057 [system_monitor.py:probe():214] Collecting system info
2024-01-21 06:11:54,123 INFO    SystemMonitor:19057 [interfaces.py:start():190] Started cpu monitoring
2024-01-21 06:11:54,123 DEBUG   HandlerThread:19057 [system_info.py:probe():151] Probing system
2024-01-21 06:11:54,124 INFO    SystemMonitor:19057 [interfaces.py:start():190] Started disk monitoring
2024-01-21 06:11:54,124 INFO    SystemMonitor:19057 [interfaces.py:start():190] Started gpuapple monitoring
2024-01-21 06:11:54,127 INFO    SystemMonitor:19057 [interfaces.py:start():190] Started memory monitoring
2024-01-21 06:11:54,129 INFO    SystemMonitor:19057 [interfaces.py:start():190] Started network monitoring
2024-01-21 06:11:54,138 DEBUG   HandlerThread:19057 [system_info.py:_probe_git():136] Probing git
2024-01-21 06:11:54,165 DEBUG   HandlerThread:19057 [system_info.py:_probe_git():144] Probing git done
2024-01-21 06:11:54,165 DEBUG   HandlerThread:19057 [system_info.py:probe():199] Probing system done
2024-01-21 06:11:54,165 DEBUG   HandlerThread:19057 [system_monitor.py:probe():223] {'os': 'macOS-13.2.1-arm64-arm-64bit', 'python': '3.9.18', 'heartbeatAt': '2024-01-20T22:11:54.124209', 'startedAt': '2024-01-20T22:11:47.633022', 'docker': None, 'cuda': None, 'args': ('--env', 'RA', '--model', 'ToM2C', '--workers', '6', '--norm-reward'), 'state': 'running', 'program': '/Users/suhuangyuan/DRA/main.py', 'codePathLocal': 'main.py', 'codePath': 'main.py', 'git': {'remote': 'git@github.com:Hither1/DRA.git', 'commit': 'f62b44b4268f087957510e98676af8dc4dcc3c75'}, 'email': 'suhither@gmail.com', 'root': '/Users/suhuangyuan/DRA', 'host': 'gens-MacBook-Pro.local', 'username': 'suhuangyuan', 'executable': '/Users/suhuangyuan/miniconda3/envs/resource/bin/python', 'cpu_count': 10, 'cpu_count_logical': 10, 'disk': {'/': {'total': 460.4317207336426, 'used': 12.228080749511719}}, 'gpuapple': {'type': 'arm', 'vendor': 'Apple'}, 'memory': {'total': 16.0}}
2024-01-21 06:11:54,166 INFO    HandlerThread:19057 [system_monitor.py:probe():224] Finished collecting system info
2024-01-21 06:11:54,166 INFO    HandlerThread:19057 [system_monitor.py:probe():227] Publishing system info
2024-01-21 06:11:54,166 DEBUG   HandlerThread:19057 [system_info.py:_save_conda():208] Saving list of conda packages installed into the current environment
2024-01-21 06:11:55,064 INFO    Thread-12 :19057 [dir_watcher.py:_on_file_created():271] file/dir created: /Users/suhuangyuan/DRA/wandb/run-20240121_061147-lvkhb8ha/files/conda-environment.yaml
2024-01-21 06:11:55,423 DEBUG   HandlerThread:19057 [system_info.py:_save_conda():220] Saving conda packages done
2024-01-21 06:11:55,423 DEBUG   HandlerThread:19057 [system_info.py:_save_code():45] Saving code
2024-01-21 06:11:55,437 DEBUG   HandlerThread:19057 [system_info.py:_save_code():66] Saving code done
2024-01-21 06:11:55,437 DEBUG   HandlerThread:19057 [system_info.py:_save_patches():83] Saving git patches
2024-01-21 06:11:55,641 DEBUG   HandlerThread:19057 [system_info.py:_save_patches():125] Saving git patches done
2024-01-21 06:11:55,641 INFO    HandlerThread:19057 [system_monitor.py:probe():229] Finished publishing system info
2024-01-21 06:11:55,644 DEBUG   SenderThread:19057 [sender.py:send():382] send: files
2024-01-21 06:11:55,644 INFO    SenderThread:19057 [sender.py:_save_file():1403] saving file wandb-metadata.json with policy now
2024-01-21 06:11:55,645 INFO    SenderThread:19057 [sender.py:_save_file():1403] saving file code/main.py with policy now
2024-01-21 06:11:55,645 INFO    SenderThread:19057 [sender.py:_save_file():1403] saving file diff.patch with policy now
2024-01-21 06:11:55,647 DEBUG   HandlerThread:19057 [handler.py:handle_request():146] handle_request: python_packages
2024-01-21 06:11:55,648 DEBUG   HandlerThread:19057 [handler.py:handle_request():146] handle_request: stop_status
2024-01-21 06:11:55,648 DEBUG   SenderThread:19057 [sender.py:send_request():409] send_request: python_packages
2024-01-21 06:11:55,648 DEBUG   HandlerThread:19057 [handler.py:handle_request():146] handle_request: internal_messages
2024-01-21 06:11:55,651 DEBUG   SenderThread:19057 [sender.py:send_request():409] send_request: stop_status
2024-01-21 06:11:56,068 INFO    Thread-12 :19057 [dir_watcher.py:_on_file_modified():288] file/dir modified: /Users/suhuangyuan/DRA/wandb/run-20240121_061147-lvkhb8ha/files/conda-environment.yaml
2024-01-21 06:11:56,069 INFO    Thread-12 :19057 [dir_watcher.py:_on_file_created():271] file/dir created: /Users/suhuangyuan/DRA/wandb/run-20240121_061147-lvkhb8ha/files/wandb-metadata.json
2024-01-21 06:11:56,069 INFO    Thread-12 :19057 [dir_watcher.py:_on_file_created():271] file/dir created: /Users/suhuangyuan/DRA/wandb/run-20240121_061147-lvkhb8ha/files/code/main.py
2024-01-21 06:11:56,069 INFO    Thread-12 :19057 [dir_watcher.py:_on_file_created():271] file/dir created: /Users/suhuangyuan/DRA/wandb/run-20240121_061147-lvkhb8ha/files/requirements.txt
2024-01-21 06:11:56,069 INFO    Thread-12 :19057 [dir_watcher.py:_on_file_created():271] file/dir created: /Users/suhuangyuan/DRA/wandb/run-20240121_061147-lvkhb8ha/files/diff.patch
2024-01-21 06:11:56,069 INFO    Thread-12 :19057 [dir_watcher.py:_on_file_created():271] file/dir created: /Users/suhuangyuan/DRA/wandb/run-20240121_061147-lvkhb8ha/files/code
2024-01-21 06:11:58,281 DEBUG   SenderThread:19057 [sender.py:send():382] send: telemetry
2024-01-21 06:11:59,090 INFO    Thread-12 :19057 [dir_watcher.py:_on_file_created():271] file/dir created: /Users/suhuangyuan/DRA/wandb/run-20240121_061147-lvkhb8ha/files/output.log
2024-01-21 06:11:59,290 DEBUG   HandlerThread:19057 [handler.py:handle_request():146] handle_request: status_report
2024-01-21 06:11:59,610 INFO    wandb-upload_0:19057 [upload_job.py:push():131] Uploaded file /var/folders/72/mvwhplb93ms91mvl36q329qh0000gn/T/tmpkm0_u2p5wandb/oy8wul26-wandb-metadata.json
2024-01-21 06:12:01,100 INFO    Thread-12 :19057 [dir_watcher.py:_on_file_modified():288] file/dir modified: /Users/suhuangyuan/DRA/wandb/run-20240121_061147-lvkhb8ha/files/output.log
2024-01-21 06:12:01,580 INFO    wandb-upload_1:19057 [upload_job.py:push():131] Uploaded file /var/folders/72/mvwhplb93ms91mvl36q329qh0000gn/T/tmpkm0_u2p5wandb/pw8ql2if-code/main.py
2024-01-21 06:12:02,165 INFO    wandb-upload_2:19057 [upload_job.py:push():131] Uploaded file /var/folders/72/mvwhplb93ms91mvl36q329qh0000gn/T/tmpkm0_u2p5wandb/kcvwxzq7-diff.patch
2024-01-21 06:12:02,903 DEBUG   HandlerThread:19057 [handler.py:handle_request():146] handle_request: partial_history
2024-01-21 06:12:02,903 DEBUG   HandlerThread:19057 [handler.py:handle_request():146] handle_request: partial_history
2024-01-21 06:12:03,112 INFO    Thread-12 :19057 [dir_watcher.py:_on_file_modified():288] file/dir modified: /Users/suhuangyuan/DRA/wandb/run-20240121_061147-lvkhb8ha/files/output.log
2024-01-21 06:12:04,908 DEBUG   HandlerThread:19057 [handler.py:handle_request():146] handle_request: status_report
2024-01-21 06:12:05,123 INFO    Thread-12 :19057 [dir_watcher.py:_on_file_modified():288] file/dir modified: /Users/suhuangyuan/DRA/wandb/run-20240121_061147-lvkhb8ha/files/output.log
2024-01-21 06:12:07,130 INFO    Thread-12 :19057 [dir_watcher.py:_on_file_modified():288] file/dir modified: /Users/suhuangyuan/DRA/wandb/run-20240121_061147-lvkhb8ha/files/output.log
2024-01-21 06:12:07,547 DEBUG   HandlerThread:19057 [handler.py:handle_request():146] handle_request: partial_history
2024-01-21 06:12:07,548 DEBUG   HandlerThread:19057 [handler.py:handle_request():146] handle_request: partial_history
2024-01-21 06:12:07,548 DEBUG   SenderThread:19057 [sender.py:send():382] send: history
2024-01-21 06:12:07,549 DEBUG   SenderThread:19057 [sender.py:send_request():409] send_request: summary_record
2024-01-21 06:12:07,549 INFO    SenderThread:19057 [sender.py:_save_file():1403] saving file wandb-summary.json with policy end
2024-01-21 06:12:08,135 INFO    Thread-12 :19057 [dir_watcher.py:_on_file_created():271] file/dir created: /Users/suhuangyuan/DRA/wandb/run-20240121_061147-lvkhb8ha/files/wandb-summary.json
2024-01-21 06:12:09,141 INFO    Thread-12 :19057 [dir_watcher.py:_on_file_modified():288] file/dir modified: /Users/suhuangyuan/DRA/wandb/run-20240121_061147-lvkhb8ha/files/output.log
2024-01-21 06:12:10,656 DEBUG   HandlerThread:19057 [handler.py:handle_request():146] handle_request: stop_status
2024-01-21 06:12:10,656 DEBUG   SenderThread:19057 [sender.py:send_request():409] send_request: stop_status
2024-01-21 06:12:10,663 DEBUG   HandlerThread:19057 [handler.py:handle_request():146] handle_request: internal_messages
2024-01-21 06:12:11,150 INFO    Thread-12 :19057 [dir_watcher.py:_on_file_modified():288] file/dir modified: /Users/suhuangyuan/DRA/wandb/run-20240121_061147-lvkhb8ha/files/output.log
2024-01-21 06:12:12,613 DEBUG   HandlerThread:19057 [handler.py:handle_request():146] handle_request: poll_exit
2024-01-21 06:12:14,316 DEBUG   SenderThread:19057 [sender.py:send():382] send: exit
2024-01-21 06:12:14,316 DEBUG   HandlerThread:19057 [handler.py:handle_request():146] handle_request: status_report
2024-01-21 06:12:14,317 INFO    SenderThread:19057 [sender.py:send_exit():589] handling exit code: 1
2024-01-21 06:12:14,318 INFO    SenderThread:19057 [sender.py:send_exit():591] handling runtime: 17
2024-01-21 06:12:14,322 INFO    SenderThread:19057 [sender.py:_save_file():1403] saving file wandb-summary.json with policy end
2024-01-21 06:12:14,323 INFO    SenderThread:19057 [sender.py:send_exit():597] send defer
2024-01-21 06:12:14,323 DEBUG   SenderThread:19057 [sender.py:send_request():409] send_request: poll_exit
2024-01-21 06:12:14,323 DEBUG   HandlerThread:19057 [handler.py:handle_request():146] handle_request: defer
2024-01-21 06:12:14,324 INFO    HandlerThread:19057 [handler.py:handle_request_defer():172] handle defer: 0
2024-01-21 06:12:14,325 DEBUG   SenderThread:19057 [sender.py:send_request():409] send_request: defer
2024-01-21 06:12:14,325 INFO    SenderThread:19057 [sender.py:send_request_defer():613] handle sender defer: 0
2024-01-21 06:12:14,325 INFO    SenderThread:19057 [sender.py:transition_state():617] send defer: 1
2024-01-21 06:12:14,325 DEBUG   HandlerThread:19057 [handler.py:handle_request():146] handle_request: defer
2024-01-21 06:12:14,325 INFO    HandlerThread:19057 [handler.py:handle_request_defer():172] handle defer: 1
2024-01-21 06:12:14,326 DEBUG   SenderThread:19057 [sender.py:send_request():409] send_request: defer
2024-01-21 06:12:14,326 INFO    SenderThread:19057 [sender.py:send_request_defer():613] handle sender defer: 1
2024-01-21 06:12:14,326 INFO    SenderThread:19057 [sender.py:transition_state():617] send defer: 2
2024-01-21 06:12:14,326 DEBUG   HandlerThread:19057 [handler.py:handle_request():146] handle_request: defer
2024-01-21 06:12:14,326 INFO    HandlerThread:19057 [handler.py:handle_request_defer():172] handle defer: 2
2024-01-21 06:12:14,326 INFO    HandlerThread:19057 [system_monitor.py:finish():203] Stopping system monitor
2024-01-21 06:12:14,326 DEBUG   SystemMonitor:19057 [system_monitor.py:_start():172] Starting system metrics aggregation loop
2024-01-21 06:12:14,326 DEBUG   SystemMonitor:19057 [system_monitor.py:_start():179] Finished system metrics aggregation loop
2024-01-21 06:12:14,327 INFO    HandlerThread:19057 [interfaces.py:finish():202] Joined cpu monitor
2024-01-21 06:12:14,327 DEBUG   SystemMonitor:19057 [system_monitor.py:_start():183] Publishing last batch of metrics
2024-01-21 06:12:14,327 INFO    HandlerThread:19057 [interfaces.py:finish():202] Joined disk monitor
2024-01-21 06:12:14,328 INFO    HandlerThread:19057 [interfaces.py:finish():202] Joined gpuapple monitor
2024-01-21 06:12:14,328 INFO    HandlerThread:19057 [interfaces.py:finish():202] Joined memory monitor
2024-01-21 06:12:14,328 INFO    HandlerThread:19057 [interfaces.py:finish():202] Joined network monitor
2024-01-21 06:12:14,328 DEBUG   SenderThread:19057 [sender.py:send_request():409] send_request: defer
2024-01-21 06:12:14,328 INFO    SenderThread:19057 [sender.py:send_request_defer():613] handle sender defer: 2
2024-01-21 06:12:14,328 INFO    SenderThread:19057 [sender.py:transition_state():617] send defer: 3
2024-01-21 06:12:14,328 DEBUG   SenderThread:19057 [sender.py:send():382] send: telemetry
2024-01-21 06:12:14,328 DEBUG   HandlerThread:19057 [handler.py:handle_request():146] handle_request: defer
2024-01-21 06:12:14,328 DEBUG   SenderThread:19057 [sender.py:send():382] send: stats
2024-01-21 06:12:14,328 INFO    HandlerThread:19057 [handler.py:handle_request_defer():172] handle defer: 3
2024-01-21 06:12:14,329 DEBUG   SenderThread:19057 [sender.py:send():382] send: history
2024-01-21 06:12:14,329 DEBUG   SenderThread:19057 [sender.py:send_request():409] send_request: summary_record
2024-01-21 06:12:14,330 INFO    SenderThread:19057 [sender.py:_save_file():1403] saving file wandb-summary.json with policy end
2024-01-21 06:12:14,330 DEBUG   SenderThread:19057 [sender.py:send_request():409] send_request: defer
2024-01-21 06:12:14,330 INFO    SenderThread:19057 [sender.py:send_request_defer():613] handle sender defer: 3
2024-01-21 06:12:14,330 INFO    SenderThread:19057 [sender.py:transition_state():617] send defer: 4
2024-01-21 06:12:14,330 DEBUG   HandlerThread:19057 [handler.py:handle_request():146] handle_request: defer
2024-01-21 06:12:14,330 INFO    HandlerThread:19057 [handler.py:handle_request_defer():172] handle defer: 4
2024-01-21 06:12:14,330 DEBUG   SenderThread:19057 [sender.py:send_request():409] send_request: defer
2024-01-21 06:12:14,330 INFO    SenderThread:19057 [sender.py:send_request_defer():613] handle sender defer: 4
2024-01-21 06:12:14,330 INFO    SenderThread:19057 [sender.py:transition_state():617] send defer: 5
2024-01-21 06:12:14,330 DEBUG   HandlerThread:19057 [handler.py:handle_request():146] handle_request: defer
2024-01-21 06:12:14,330 INFO    HandlerThread:19057 [handler.py:handle_request_defer():172] handle defer: 5
2024-01-21 06:12:14,331 DEBUG   SenderThread:19057 [sender.py:send():382] send: summary
2024-01-21 06:12:14,331 INFO    SenderThread:19057 [sender.py:_save_file():1403] saving file wandb-summary.json with policy end
2024-01-21 06:12:14,331 DEBUG   SenderThread:19057 [sender.py:send_request():409] send_request: defer
2024-01-21 06:12:14,331 INFO    SenderThread:19057 [sender.py:send_request_defer():613] handle sender defer: 5
2024-01-21 06:12:14,331 INFO    SenderThread:19057 [sender.py:transition_state():617] send defer: 6
2024-01-21 06:12:14,331 DEBUG   HandlerThread:19057 [handler.py:handle_request():146] handle_request: defer
2024-01-21 06:12:14,331 INFO    HandlerThread:19057 [handler.py:handle_request_defer():172] handle defer: 6
2024-01-21 06:12:14,331 DEBUG   SenderThread:19057 [sender.py:send_request():409] send_request: defer
2024-01-21 06:12:14,332 INFO    SenderThread:19057 [sender.py:send_request_defer():613] handle sender defer: 6
2024-01-21 06:12:14,335 DEBUG   HandlerThread:19057 [handler.py:handle_request():146] handle_request: status_report
2024-01-21 06:12:14,620 DEBUG   HandlerThread:19057 [handler.py:handle_request():146] handle_request: poll_exit
2024-01-21 06:12:15,170 INFO    Thread-12 :19057 [dir_watcher.py:_on_file_modified():288] file/dir modified: /Users/suhuangyuan/DRA/wandb/run-20240121_061147-lvkhb8ha/files/wandb-summary.json
2024-01-21 06:12:17,176 INFO    Thread-12 :19057 [dir_watcher.py:_on_file_modified():288] file/dir modified: /Users/suhuangyuan/DRA/wandb/run-20240121_061147-lvkhb8ha/files/output.log
2024-01-21 06:12:19,639 DEBUG   HandlerThread:19057 [handler.py:handle_request():146] handle_request: keepalive
2024-01-21 06:12:20,749 WARNING StreamThr :19057 [internal.py:is_dead():414] Internal process exiting, parent pid 19024 disappeared
2024-01-21 06:12:20,749 ERROR   StreamThr :19057 [internal.py:wandb_internal():152] Internal process shutdown.
2024-01-21 06:12:21,645 INFO    WriterThread:19057 [datastore.py:close():296] close: /Users/suhuangyuan/DRA/wandb/run-20240121_061147-lvkhb8ha/run-lvkhb8ha.wandb
2024-01-21 06:12:21,645 INFO    HandlerThread:19057 [handler.py:finish():869] shutting down handler
2024-01-21 06:12:36,113 INFO    SenderThread:19057 [sender.py:transition_state():617] send defer: 7
2024-01-21 06:12:36,114 INFO    SenderThread:19057 [sender.py:finish():1572] shutting down sender
2024-01-21 06:12:36,247 INFO    Thread-12 :19057 [dir_watcher.py:_on_file_modified():288] file/dir modified: /Users/suhuangyuan/DRA/wandb/run-20240121_061147-lvkhb8ha/files/config.yaml
2024-01-21 06:12:38,378 INFO    SenderThread:19057 [dir_watcher.py:finish():358] shutting down directory watcher
2024-01-21 06:12:39,255 INFO    SenderThread:19057 [dir_watcher.py:_on_file_modified():288] file/dir modified: /Users/suhuangyuan/DRA/wandb/run-20240121_061147-lvkhb8ha/files/output.log
2024-01-21 06:12:39,256 INFO    SenderThread:19057 [dir_watcher.py:finish():388] scan: /Users/suhuangyuan/DRA/wandb/run-20240121_061147-lvkhb8ha/files
2024-01-21 06:12:39,256 INFO    SenderThread:19057 [dir_watcher.py:finish():402] scan save: /Users/suhuangyuan/DRA/wandb/run-20240121_061147-lvkhb8ha/files/diff.patch diff.patch
2024-01-21 06:12:39,256 INFO    SenderThread:19057 [dir_watcher.py:finish():402] scan save: /Users/suhuangyuan/DRA/wandb/run-20240121_061147-lvkhb8ha/files/requirements.txt requirements.txt
2024-01-21 06:12:39,256 INFO    SenderThread:19057 [dir_watcher.py:finish():402] scan save: /Users/suhuangyuan/DRA/wandb/run-20240121_061147-lvkhb8ha/files/output.log output.log
2024-01-21 06:12:39,259 INFO    SenderThread:19057 [dir_watcher.py:finish():402] scan save: /Users/suhuangyuan/DRA/wandb/run-20240121_061147-lvkhb8ha/files/config.yaml config.yaml
2024-01-21 06:12:39,261 INFO    SenderThread:19057 [dir_watcher.py:finish():402] scan save: /Users/suhuangyuan/DRA/wandb/run-20240121_061147-lvkhb8ha/files/wandb-summary.json wandb-summary.json
2024-01-21 06:12:39,262 INFO    SenderThread:19057 [dir_watcher.py:finish():402] scan save: /Users/suhuangyuan/DRA/wandb/run-20240121_061147-lvkhb8ha/files/conda-environment.yaml conda-environment.yaml
2024-01-21 06:12:39,262 INFO    SenderThread:19057 [dir_watcher.py:finish():402] scan save: /Users/suhuangyuan/DRA/wandb/run-20240121_061147-lvkhb8ha/files/wandb-metadata.json wandb-metadata.json
2024-01-21 06:12:39,272 INFO    SenderThread:19057 [dir_watcher.py:finish():402] scan save: /Users/suhuangyuan/DRA/wandb/run-20240121_061147-lvkhb8ha/files/code/main.py code/main.py
2024-01-21 06:12:39,273 INFO    SenderThread:19057 [file_pusher.py:finish():175] shutting down file pusher
2024-01-21 06:12:39,274 INFO    SenderThread:19057 [file_pusher.py:join():181] waiting for file pusher
2024-01-21 06:12:59,276 INFO    wandb-upload_2:19057 [retry.py:__call__():172] Retry attempt failed:
Traceback (most recent call last):
  File "/Users/suhuangyuan/miniconda3/envs/resource/lib/python3.9/site-packages/urllib3/connectionpool.py", line 536, in _make_request
    response = conn.getresponse()
  File "/Users/suhuangyuan/miniconda3/envs/resource/lib/python3.9/site-packages/urllib3/connection.py", line 461, in getresponse
    httplib_response = super().getresponse()
  File "/Users/suhuangyuan/miniconda3/envs/resource/lib/python3.9/http/client.py", line 1377, in getresponse
    response.begin()
  File "/Users/suhuangyuan/miniconda3/envs/resource/lib/python3.9/http/client.py", line 320, in begin
    version, status, reason = self._read_status()
  File "/Users/suhuangyuan/miniconda3/envs/resource/lib/python3.9/http/client.py", line 281, in _read_status
    line = str(self.fp.readline(_MAXLINE + 1), "iso-8859-1")
  File "/Users/suhuangyuan/miniconda3/envs/resource/lib/python3.9/socket.py", line 704, in readinto
    return self._sock.recv_into(b)
  File "/Users/suhuangyuan/miniconda3/envs/resource/lib/python3.9/ssl.py", line 1275, in recv_into
    return self.read(nbytes, buffer)
  File "/Users/suhuangyuan/miniconda3/envs/resource/lib/python3.9/ssl.py", line 1133, in read
    return self._sslobj.read(len, buffer)
socket.timeout: The read operation timed out

The above exception was the direct cause of the following exception:

Traceback (most recent call last):
  File "/Users/suhuangyuan/miniconda3/envs/resource/lib/python3.9/site-packages/requests/adapters.py", line 486, in send
    resp = conn.urlopen(
  File "/Users/suhuangyuan/miniconda3/envs/resource/lib/python3.9/site-packages/urllib3/connectionpool.py", line 844, in urlopen
    retries = retries.increment(
  File "/Users/suhuangyuan/miniconda3/envs/resource/lib/python3.9/site-packages/urllib3/util/retry.py", line 470, in increment
    raise reraise(type(error), error, _stacktrace)
  File "/Users/suhuangyuan/miniconda3/envs/resource/lib/python3.9/site-packages/urllib3/util/util.py", line 39, in reraise
    raise value
  File "/Users/suhuangyuan/miniconda3/envs/resource/lib/python3.9/site-packages/urllib3/connectionpool.py", line 790, in urlopen
    response = self._make_request(
  File "/Users/suhuangyuan/miniconda3/envs/resource/lib/python3.9/site-packages/urllib3/connectionpool.py", line 538, in _make_request
    self._raise_timeout(err=e, url=url, timeout_value=read_timeout)
  File "/Users/suhuangyuan/miniconda3/envs/resource/lib/python3.9/site-packages/urllib3/connectionpool.py", line 370, in _raise_timeout
    raise ReadTimeoutError(
urllib3.exceptions.ReadTimeoutError: HTTPSConnectionPool(host='api.wandb.ai', port=443): Read timed out. (read timeout=20)

During handling of the above exception, another exception occurred:

Traceback (most recent call last):
  File "/Users/suhuangyuan/miniconda3/envs/resource/lib/python3.9/site-packages/wandb/sdk/lib/retry.py", line 131, in __call__
    result = self._call_fn(*args, **kwargs)
  File "/Users/suhuangyuan/miniconda3/envs/resource/lib/python3.9/site-packages/wandb/sdk/internal/internal_api.py", line 369, in execute
    return self.client.execute(*args, **kwargs)  # type: ignore
  File "/Users/suhuangyuan/miniconda3/envs/resource/lib/python3.9/site-packages/wandb/vendor/gql-0.2.0/wandb_gql/client.py", line 52, in execute
    result = self._get_result(document, *args, **kwargs)
  File "/Users/suhuangyuan/miniconda3/envs/resource/lib/python3.9/site-packages/wandb/vendor/gql-0.2.0/wandb_gql/client.py", line 60, in _get_result
    return self.transport.execute(document, *args, **kwargs)
  File "/Users/suhuangyuan/miniconda3/envs/resource/lib/python3.9/site-packages/wandb/sdk/lib/gql_request.py", line 58, in execute
    request = self.session.post(self.url, **post_args)
  File "/Users/suhuangyuan/miniconda3/envs/resource/lib/python3.9/site-packages/requests/sessions.py", line 637, in post
    return self.request("POST", url, data=data, json=json, **kwargs)
  File "/Users/suhuangyuan/miniconda3/envs/resource/lib/python3.9/site-packages/requests/sessions.py", line 589, in request
    resp = self.send(prep, **send_kwargs)
  File "/Users/suhuangyuan/miniconda3/envs/resource/lib/python3.9/site-packages/requests/sessions.py", line 703, in send
    r = adapter.send(request, **kwargs)
  File "/Users/suhuangyuan/miniconda3/envs/resource/lib/python3.9/site-packages/requests/adapters.py", line 532, in send
    raise ReadTimeout(e, request=request)
requests.exceptions.ReadTimeout: HTTPSConnectionPool(host='api.wandb.ai', port=443): Read timed out. (read timeout=20)
2024-01-21 06:12:59,603 INFO    wandb-upload_4:19057 [upload_job.py:push():131] Uploaded file /Users/suhuangyuan/DRA/wandb/run-20240121_061147-lvkhb8ha/files/conda-environment.yaml
2024-01-21 06:13:00,098 ERROR   wandb-upload_0:19057 [internal_api.py:upload_file():2765] upload_file exception https://storage.googleapis.com/wandb-production.appspot.com/iris-tajwar/ToM2C/lvkhb8ha/requirements.txt?Expires=1705875159&GoogleAccessId=gorilla-files-url-signer-man%40wandb-production.iam.gserviceaccount.com&Signature=T7PE%2Bxmnn8Rt7REq%2FoA1fMSI30LUKKxNRC6vZ2jmyP8TA55akjEDUPMcI9w6VB6UULsUwwnfSwHZuoenbpAxPCSpb6IrX7GW9zUw7p4QYnL1Hammntr3KOjWKNTAq3CHV4n1i9atKnnk4pHmxzkc42URU3OeZQ16gA%2B2aoYOsGnLpsBw4mYGAhcPE9yORaYqxKwf4NM2HbintjkJeOukA42wA5san4ov9ffXAgG%2B6Rq5ynVsxNvkISOh0t13rcs5SiKecJt4jx1BWUXF6ytAGQTecw5JnT26W3hR1kQlwpy39C3rd%2FlpvZXuo4H9el2afHjjTuWl2JAu98NlUDIalg%3D%3D: ('Connection aborted.', TimeoutError(60, 'Operation timed out'))
2024-01-21 06:13:00,098 ERROR   wandb-upload_0:19057 [internal_api.py:upload_file():2767] upload_file request headers: {'User-Agent': 'python-requests/2.31.0', 'Accept-Encoding': 'gzip, deflate', 'Accept': '*/*', 'Connection': 'keep-alive', 'Content-Length': '856'}
2024-01-21 06:13:00,098 ERROR   wandb-upload_0:19057 [internal_api.py:upload_file():2769] upload_file response body: 
2024-01-21 06:13:01,470 INFO    wandb-upload_2:19057 [upload_job.py:push():131] Uploaded file /Users/suhuangyuan/DRA/wandb/run-20240121_061147-lvkhb8ha/files/output.log
2024-01-21 06:13:01,601 INFO    wandb-upload_0:19057 [upload_job.py:push():131] Uploaded file /Users/suhuangyuan/DRA/wandb/run-20240121_061147-lvkhb8ha/files/requirements.txt
2024-01-21 06:13:16,389 ERROR   wandb-upload_1:19057 [internal_api.py:upload_file():2765] upload_file exception https://storage.googleapis.com/wandb-production.appspot.com/iris-tajwar/ToM2C/lvkhb8ha/config.yaml?Expires=1705875159&GoogleAccessId=gorilla-files-url-signer-man%40wandb-production.iam.gserviceaccount.com&Signature=vbHaN0SQzjNbT7F6AbarjfqCApJ7z3UOFWKar7fzwj%2FQXe5ph592Z0Ba%2FLFwx%2B1500b1JlUNI6fCHyuMz72dlbt2hLESvEscgx6kWO2iauTMb5GJva5BU8qwRdxCHV5uYkUPhj05q65gzbXprGQa4F92wH6%2B4a05QnDbdtfCQUsC%2FUKW6pTdWg16Bw%2BbLoNcNhTShJAcay0JbjupSaP9%2B3FHwOsvcu3pLEKnUajcRZekzT94Q8L6RVr0g2yo7HGY%2FhVFQZVL6vhGDpBGBXynArxiUReq18ROS0aNcenZGwxbnk5XYyECOn6oE9epXFvxd4DGqB7PzptoBIrC3HiABA%3D%3D: ('Connection aborted.', TimeoutError(60, 'Operation timed out'))
2024-01-21 06:13:16,390 ERROR   wandb-upload_1:19057 [internal_api.py:upload_file():2767] upload_file request headers: {'User-Agent': 'python-requests/2.31.0', 'Accept-Encoding': 'gzip, deflate', 'Accept': '*/*', 'Connection': 'keep-alive', 'Content-Length': '428'}
2024-01-21 06:13:16,390 ERROR   wandb-upload_1:19057 [internal_api.py:upload_file():2769] upload_file response body: 
2024-01-21 06:13:18,111 INFO    wandb-upload_1:19057 [upload_job.py:push():131] Uploaded file /Users/suhuangyuan/DRA/wandb/run-20240121_061147-lvkhb8ha/files/config.yaml
2024-01-21 06:15:11,194 ERROR   wandb-upload_3:19057 [internal_api.py:upload_file():2765] upload_file exception https://storage.googleapis.com/wandb-production.appspot.com/iris-tajwar/ToM2C/lvkhb8ha/wandb-summary.json?Expires=1705875178&GoogleAccessId=gorilla-files-url-signer-man%40wandb-production.iam.gserviceaccount.com&Signature=gv5Khbo3InvkfBwCzqhXZ8NTAb5wcvUmCNWv%2FcCpHf5zPKI1WZFlGbUAmO72BCmJiibYQB%2FSgUYVjHMyOJi4NRzI34p%2F4B7J4WIaaLuJMOGHkaKMMFlvj8jDTEr92haVwAqTIE0w%2Buv8dkRyJrCZPvCc8AO1aBICKXOiAOi6mMdEvdo81B7EXr%2BbSX5CwiA6IngguOd3s180ygkika8o%2FYTtwcmCOihw3z3Q6wox4QcrVc6mMqlUOtEzkBn4uKCD4f44bEJcUdgD6YVReScGspWFgScKnY%2BIq00h9io85M3i2gocYUMAeoOnD9ky%2B%2FWyq64YCbYQLVP35GcwuL7jHQ%3D%3D: ('Connection aborted.', TimeoutError(60, 'Operation timed out'))
2024-01-21 06:15:11,197 ERROR   wandb-upload_3:19057 [internal_api.py:upload_file():2767] upload_file request headers: {'User-Agent': 'python-requests/2.31.0', 'Accept-Encoding': 'gzip, deflate', 'Accept': '*/*', 'Connection': 'keep-alive', 'Content-Length': '160'}
2024-01-21 06:15:11,197 ERROR   wandb-upload_3:19057 [internal_api.py:upload_file():2769] upload_file response body: 
2024-01-21 06:15:11,198 INFO    wandb-upload_3:19057 [retry.py:__call__():172] Retry attempt failed:
Traceback (most recent call last):
  File "/Users/suhuangyuan/miniconda3/envs/resource/lib/python3.9/site-packages/urllib3/connectionpool.py", line 790, in urlopen
    response = self._make_request(
  File "/Users/suhuangyuan/miniconda3/envs/resource/lib/python3.9/site-packages/urllib3/connectionpool.py", line 536, in _make_request
    response = conn.getresponse()
  File "/Users/suhuangyuan/miniconda3/envs/resource/lib/python3.9/site-packages/urllib3/connection.py", line 461, in getresponse
    httplib_response = super().getresponse()
  File "/Users/suhuangyuan/miniconda3/envs/resource/lib/python3.9/http/client.py", line 1377, in getresponse
    response.begin()
  File "/Users/suhuangyuan/miniconda3/envs/resource/lib/python3.9/http/client.py", line 320, in begin
    version, status, reason = self._read_status()
  File "/Users/suhuangyuan/miniconda3/envs/resource/lib/python3.9/http/client.py", line 281, in _read_status
    line = str(self.fp.readline(_MAXLINE + 1), "iso-8859-1")
  File "/Users/suhuangyuan/miniconda3/envs/resource/lib/python3.9/socket.py", line 704, in readinto
    return self._sock.recv_into(b)
  File "/Users/suhuangyuan/miniconda3/envs/resource/lib/python3.9/ssl.py", line 1275, in recv_into
    return self.read(nbytes, buffer)
  File "/Users/suhuangyuan/miniconda3/envs/resource/lib/python3.9/ssl.py", line 1133, in read
    return self._sslobj.read(len, buffer)
TimeoutError: [Errno 60] Operation timed out

During handling of the above exception, another exception occurred:

Traceback (most recent call last):
  File "/Users/suhuangyuan/miniconda3/envs/resource/lib/python3.9/site-packages/requests/adapters.py", line 486, in send
    resp = conn.urlopen(
  File "/Users/suhuangyuan/miniconda3/envs/resource/lib/python3.9/site-packages/urllib3/connectionpool.py", line 844, in urlopen
    retries = retries.increment(
  File "/Users/suhuangyuan/miniconda3/envs/resource/lib/python3.9/site-packages/urllib3/util/retry.py", line 470, in increment
    raise reraise(type(error), error, _stacktrace)
  File "/Users/suhuangyuan/miniconda3/envs/resource/lib/python3.9/site-packages/urllib3/util/util.py", line 38, in reraise
    raise value.with_traceback(tb)
  File "/Users/suhuangyuan/miniconda3/envs/resource/lib/python3.9/site-packages/urllib3/connectionpool.py", line 790, in urlopen
    response = self._make_request(
  File "/Users/suhuangyuan/miniconda3/envs/resource/lib/python3.9/site-packages/urllib3/connectionpool.py", line 536, in _make_request
    response = conn.getresponse()
  File "/Users/suhuangyuan/miniconda3/envs/resource/lib/python3.9/site-packages/urllib3/connection.py", line 461, in getresponse
    httplib_response = super().getresponse()
  File "/Users/suhuangyuan/miniconda3/envs/resource/lib/python3.9/http/client.py", line 1377, in getresponse
    response.begin()
  File "/Users/suhuangyuan/miniconda3/envs/resource/lib/python3.9/http/client.py", line 320, in begin
    version, status, reason = self._read_status()
  File "/Users/suhuangyuan/miniconda3/envs/resource/lib/python3.9/http/client.py", line 281, in _read_status
    line = str(self.fp.readline(_MAXLINE + 1), "iso-8859-1")
  File "/Users/suhuangyuan/miniconda3/envs/resource/lib/python3.9/socket.py", line 704, in readinto
    return self._sock.recv_into(b)
  File "/Users/suhuangyuan/miniconda3/envs/resource/lib/python3.9/ssl.py", line 1275, in recv_into
    return self.read(nbytes, buffer)
  File "/Users/suhuangyuan/miniconda3/envs/resource/lib/python3.9/ssl.py", line 1133, in read
    return self._sslobj.read(len, buffer)
urllib3.exceptions.ProtocolError: ('Connection aborted.', TimeoutError(60, 'Operation timed out'))

During handling of the above exception, another exception occurred:

Traceback (most recent call last):
  File "/Users/suhuangyuan/miniconda3/envs/resource/lib/python3.9/site-packages/wandb/sdk/internal/internal_api.py", line 2758, in upload_file
    response = self._upload_file_session.put(
  File "/Users/suhuangyuan/miniconda3/envs/resource/lib/python3.9/site-packages/requests/sessions.py", line 649, in put
    return self.request("PUT", url, data=data, **kwargs)
  File "/Users/suhuangyuan/miniconda3/envs/resource/lib/python3.9/site-packages/requests/sessions.py", line 589, in request
    resp = self.send(prep, **send_kwargs)
  File "/Users/suhuangyuan/miniconda3/envs/resource/lib/python3.9/site-packages/requests/sessions.py", line 703, in send
    r = adapter.send(request, **kwargs)
  File "/Users/suhuangyuan/miniconda3/envs/resource/lib/python3.9/site-packages/requests/adapters.py", line 501, in send
    raise ConnectionError(err, request=request)
requests.exceptions.ConnectionError: ('Connection aborted.', TimeoutError(60, 'Operation timed out'))

During handling of the above exception, another exception occurred:

Traceback (most recent call last):
  File "/Users/suhuangyuan/miniconda3/envs/resource/lib/python3.9/site-packages/wandb/sdk/lib/retry.py", line 131, in __call__
    result = self._call_fn(*args, **kwargs)
  File "/Users/suhuangyuan/miniconda3/envs/resource/lib/python3.9/site-packages/wandb/sdk/internal/internal_api.py", line 2789, in upload_file
    raise _e.with_traceback(sys.exc_info()[2])
  File "/Users/suhuangyuan/miniconda3/envs/resource/lib/python3.9/site-packages/wandb/sdk/internal/internal_api.py", line 2758, in upload_file
    response = self._upload_file_session.put(
  File "/Users/suhuangyuan/miniconda3/envs/resource/lib/python3.9/site-packages/requests/sessions.py", line 649, in put
    return self.request("PUT", url, data=data, **kwargs)
  File "/Users/suhuangyuan/miniconda3/envs/resource/lib/python3.9/site-packages/requests/sessions.py", line 589, in request
    resp = self.send(prep, **send_kwargs)
  File "/Users/suhuangyuan/miniconda3/envs/resource/lib/python3.9/site-packages/requests/sessions.py", line 703, in send
    r = adapter.send(request, **kwargs)
  File "/Users/suhuangyuan/miniconda3/envs/resource/lib/python3.9/site-packages/requests/adapters.py", line 501, in send
    raise ConnectionError(err, request=request)
wandb.sdk.lib.retry.TransientError: None
2024-01-21 06:15:11,219 ERROR   wandb-upload_3:19057 [upload_job.py:push():134] Failed to upload file: /Users/suhuangyuan/DRA/wandb/run-20240121_061147-lvkhb8ha/files/wandb-summary.json
Traceback (most recent call last):
  File "/Users/suhuangyuan/miniconda3/envs/resource/lib/python3.9/site-packages/urllib3/connectionpool.py", line 790, in urlopen
    response = self._make_request(
  File "/Users/suhuangyuan/miniconda3/envs/resource/lib/python3.9/site-packages/urllib3/connectionpool.py", line 536, in _make_request
    response = conn.getresponse()
  File "/Users/suhuangyuan/miniconda3/envs/resource/lib/python3.9/site-packages/urllib3/connection.py", line 461, in getresponse
    httplib_response = super().getresponse()
  File "/Users/suhuangyuan/miniconda3/envs/resource/lib/python3.9/http/client.py", line 1377, in getresponse
    response.begin()
  File "/Users/suhuangyuan/miniconda3/envs/resource/lib/python3.9/http/client.py", line 320, in begin
    version, status, reason = self._read_status()
  File "/Users/suhuangyuan/miniconda3/envs/resource/lib/python3.9/http/client.py", line 281, in _read_status
    line = str(self.fp.readline(_MAXLINE + 1), "iso-8859-1")
  File "/Users/suhuangyuan/miniconda3/envs/resource/lib/python3.9/socket.py", line 704, in readinto
    return self._sock.recv_into(b)
  File "/Users/suhuangyuan/miniconda3/envs/resource/lib/python3.9/ssl.py", line 1275, in recv_into
    return self.read(nbytes, buffer)
  File "/Users/suhuangyuan/miniconda3/envs/resource/lib/python3.9/ssl.py", line 1133, in read
    return self._sslobj.read(len, buffer)
TimeoutError: [Errno 60] Operation timed out

During handling of the above exception, another exception occurred:

Traceback (most recent call last):
  File "/Users/suhuangyuan/miniconda3/envs/resource/lib/python3.9/site-packages/requests/adapters.py", line 486, in send
    resp = conn.urlopen(
  File "/Users/suhuangyuan/miniconda3/envs/resource/lib/python3.9/site-packages/urllib3/connectionpool.py", line 844, in urlopen
    retries = retries.increment(
  File "/Users/suhuangyuan/miniconda3/envs/resource/lib/python3.9/site-packages/urllib3/util/retry.py", line 470, in increment
    raise reraise(type(error), error, _stacktrace)
  File "/Users/suhuangyuan/miniconda3/envs/resource/lib/python3.9/site-packages/urllib3/util/util.py", line 38, in reraise
    raise value.with_traceback(tb)
  File "/Users/suhuangyuan/miniconda3/envs/resource/lib/python3.9/site-packages/urllib3/connectionpool.py", line 790, in urlopen
    response = self._make_request(
  File "/Users/suhuangyuan/miniconda3/envs/resource/lib/python3.9/site-packages/urllib3/connectionpool.py", line 536, in _make_request
    response = conn.getresponse()
  File "/Users/suhuangyuan/miniconda3/envs/resource/lib/python3.9/site-packages/urllib3/connection.py", line 461, in getresponse
    httplib_response = super().getresponse()
  File "/Users/suhuangyuan/miniconda3/envs/resource/lib/python3.9/http/client.py", line 1377, in getresponse
    response.begin()
  File "/Users/suhuangyuan/miniconda3/envs/resource/lib/python3.9/http/client.py", line 320, in begin
    version, status, reason = self._read_status()
  File "/Users/suhuangyuan/miniconda3/envs/resource/lib/python3.9/http/client.py", line 281, in _read_status
    line = str(self.fp.readline(_MAXLINE + 1), "iso-8859-1")
  File "/Users/suhuangyuan/miniconda3/envs/resource/lib/python3.9/socket.py", line 704, in readinto
    return self._sock.recv_into(b)
  File "/Users/suhuangyuan/miniconda3/envs/resource/lib/python3.9/ssl.py", line 1275, in recv_into
    return self.read(nbytes, buffer)
  File "/Users/suhuangyuan/miniconda3/envs/resource/lib/python3.9/ssl.py", line 1133, in read
    return self._sslobj.read(len, buffer)
urllib3.exceptions.ProtocolError: ('Connection aborted.', TimeoutError(60, 'Operation timed out'))

During handling of the above exception, another exception occurred:

Traceback (most recent call last):
  File "/Users/suhuangyuan/miniconda3/envs/resource/lib/python3.9/site-packages/wandb/sdk/internal/internal_api.py", line 2758, in upload_file
    response = self._upload_file_session.put(
  File "/Users/suhuangyuan/miniconda3/envs/resource/lib/python3.9/site-packages/requests/sessions.py", line 649, in put
    return self.request("PUT", url, data=data, **kwargs)
  File "/Users/suhuangyuan/miniconda3/envs/resource/lib/python3.9/site-packages/requests/sessions.py", line 589, in request
    resp = self.send(prep, **send_kwargs)
  File "/Users/suhuangyuan/miniconda3/envs/resource/lib/python3.9/site-packages/requests/sessions.py", line 703, in send
    r = adapter.send(request, **kwargs)
  File "/Users/suhuangyuan/miniconda3/envs/resource/lib/python3.9/site-packages/requests/adapters.py", line 501, in send
    raise ConnectionError(err, request=request)
requests.exceptions.ConnectionError: ('Connection aborted.', TimeoutError(60, 'Operation timed out'))

During handling of the above exception, another exception occurred:

Traceback (most recent call last):
  File "/Users/suhuangyuan/miniconda3/envs/resource/lib/python3.9/site-packages/wandb/sdk/lib/retry.py", line 131, in __call__
    result = self._call_fn(*args, **kwargs)
  File "/Users/suhuangyuan/miniconda3/envs/resource/lib/python3.9/site-packages/wandb/sdk/internal/internal_api.py", line 2789, in upload_file
    raise _e.with_traceback(sys.exc_info()[2])
  File "/Users/suhuangyuan/miniconda3/envs/resource/lib/python3.9/site-packages/wandb/sdk/internal/internal_api.py", line 2758, in upload_file
    response = self._upload_file_session.put(
  File "/Users/suhuangyuan/miniconda3/envs/resource/lib/python3.9/site-packages/requests/sessions.py", line 649, in put
    return self.request("PUT", url, data=data, **kwargs)
  File "/Users/suhuangyuan/miniconda3/envs/resource/lib/python3.9/site-packages/requests/sessions.py", line 589, in request
    resp = self.send(prep, **send_kwargs)
  File "/Users/suhuangyuan/miniconda3/envs/resource/lib/python3.9/site-packages/requests/sessions.py", line 703, in send
    r = adapter.send(request, **kwargs)
  File "/Users/suhuangyuan/miniconda3/envs/resource/lib/python3.9/site-packages/requests/adapters.py", line 501, in send
    raise ConnectionError(err, request=request)
wandb.sdk.lib.retry.TransientError: None

During handling of the above exception, another exception occurred:

Traceback (most recent call last):
  File "/Users/suhuangyuan/miniconda3/envs/resource/lib/python3.9/site-packages/wandb/apis/normalize.py", line 41, in wrapper
    return func(*args, **kwargs)
  File "/Users/suhuangyuan/miniconda3/envs/resource/lib/python3.9/site-packages/wandb/sdk/lib/retry.py", line 212, in wrapped_fn
    return retrier(*args, **kargs)
  File "/Users/suhuangyuan/miniconda3/envs/resource/lib/python3.9/site-packages/wandb/sdk/lib/retry.py", line 183, in __call__
    wandb.termlog(
  File "/Users/suhuangyuan/miniconda3/envs/resource/lib/python3.9/site-packages/wandb/errors/term.py", line 39, in termlog
    _log(
  File "/Users/suhuangyuan/miniconda3/envs/resource/lib/python3.9/site-packages/wandb/errors/term.py", line 95, in _log
    click.echo(line, file=sys.stderr, nl=newline)
  File "/Users/suhuangyuan/miniconda3/envs/resource/lib/python3.9/site-packages/click/utils.py", line 318, in echo
    file.write(out)  # type: ignore
OSError: [Errno 5] Input/output error

During handling of the above exception, another exception occurred:

Traceback (most recent call last):
  File "/Users/suhuangyuan/miniconda3/envs/resource/lib/python3.9/site-packages/wandb/filesync/upload_job.py", line 125, in push
    self._api.upload_file_retry(
  File "/Users/suhuangyuan/miniconda3/envs/resource/lib/python3.9/site-packages/wandb/apis/normalize.py", line 87, in wrapper
    raise CommError(message, err).with_traceback(sys.exc_info()[2])
  File "/Users/suhuangyuan/miniconda3/envs/resource/lib/python3.9/site-packages/wandb/apis/normalize.py", line 41, in wrapper
    return func(*args, **kwargs)
  File "/Users/suhuangyuan/miniconda3/envs/resource/lib/python3.9/site-packages/wandb/sdk/lib/retry.py", line 212, in wrapped_fn
    return retrier(*args, **kargs)
  File "/Users/suhuangyuan/miniconda3/envs/resource/lib/python3.9/site-packages/wandb/sdk/lib/retry.py", line 183, in __call__
    wandb.termlog(
  File "/Users/suhuangyuan/miniconda3/envs/resource/lib/python3.9/site-packages/wandb/errors/term.py", line 39, in termlog
    _log(
  File "/Users/suhuangyuan/miniconda3/envs/resource/lib/python3.9/site-packages/wandb/errors/term.py", line 95, in _log
    click.echo(line, file=sys.stderr, nl=newline)
  File "/Users/suhuangyuan/miniconda3/envs/resource/lib/python3.9/site-packages/click/utils.py", line 318, in echo
    file.write(out)  # type: ignore
wandb.errors.CommError: [Errno 5] Input/output error
2024-01-21 06:15:13,255 ERROR   Thread-11 :19057 [step_upload.py:_handle_event():200] Failed to upload file: /Users/suhuangyuan/DRA/wandb/run-20240121_061147-lvkhb8ha/files/wandb-summary.json
Traceback (most recent call last):
  File "/Users/suhuangyuan/miniconda3/envs/resource/lib/python3.9/site-packages/urllib3/connectionpool.py", line 790, in urlopen
    response = self._make_request(
  File "/Users/suhuangyuan/miniconda3/envs/resource/lib/python3.9/site-packages/urllib3/connectionpool.py", line 536, in _make_request
    response = conn.getresponse()
  File "/Users/suhuangyuan/miniconda3/envs/resource/lib/python3.9/site-packages/urllib3/connection.py", line 461, in getresponse
    httplib_response = super().getresponse()
  File "/Users/suhuangyuan/miniconda3/envs/resource/lib/python3.9/http/client.py", line 1377, in getresponse
    response.begin()
  File "/Users/suhuangyuan/miniconda3/envs/resource/lib/python3.9/http/client.py", line 320, in begin
    version, status, reason = self._read_status()
  File "/Users/suhuangyuan/miniconda3/envs/resource/lib/python3.9/http/client.py", line 281, in _read_status
    line = str(self.fp.readline(_MAXLINE + 1), "iso-8859-1")
  File "/Users/suhuangyuan/miniconda3/envs/resource/lib/python3.9/socket.py", line 704, in readinto
    return self._sock.recv_into(b)
  File "/Users/suhuangyuan/miniconda3/envs/resource/lib/python3.9/ssl.py", line 1275, in recv_into
    return self.read(nbytes, buffer)
  File "/Users/suhuangyuan/miniconda3/envs/resource/lib/python3.9/ssl.py", line 1133, in read
    return self._sslobj.read(len, buffer)
TimeoutError: [Errno 60] Operation timed out

During handling of the above exception, another exception occurred:

Traceback (most recent call last):
  File "/Users/suhuangyuan/miniconda3/envs/resource/lib/python3.9/site-packages/requests/adapters.py", line 486, in send
    resp = conn.urlopen(
  File "/Users/suhuangyuan/miniconda3/envs/resource/lib/python3.9/site-packages/urllib3/connectionpool.py", line 844, in urlopen
    retries = retries.increment(
  File "/Users/suhuangyuan/miniconda3/envs/resource/lib/python3.9/site-packages/urllib3/util/retry.py", line 470, in increment
    raise reraise(type(error), error, _stacktrace)
  File "/Users/suhuangyuan/miniconda3/envs/resource/lib/python3.9/site-packages/urllib3/util/util.py", line 38, in reraise
    raise value.with_traceback(tb)
  File "/Users/suhuangyuan/miniconda3/envs/resource/lib/python3.9/site-packages/urllib3/connectionpool.py", line 790, in urlopen
    response = self._make_request(
  File "/Users/suhuangyuan/miniconda3/envs/resource/lib/python3.9/site-packages/urllib3/connectionpool.py", line 536, in _make_request
    response = conn.getresponse()
  File "/Users/suhuangyuan/miniconda3/envs/resource/lib/python3.9/site-packages/urllib3/connection.py", line 461, in getresponse
    httplib_response = super().getresponse()
  File "/Users/suhuangyuan/miniconda3/envs/resource/lib/python3.9/http/client.py", line 1377, in getresponse
    response.begin()
  File "/Users/suhuangyuan/miniconda3/envs/resource/lib/python3.9/http/client.py", line 320, in begin
    version, status, reason = self._read_status()
  File "/Users/suhuangyuan/miniconda3/envs/resource/lib/python3.9/http/client.py", line 281, in _read_status
    line = str(self.fp.readline(_MAXLINE + 1), "iso-8859-1")
  File "/Users/suhuangyuan/miniconda3/envs/resource/lib/python3.9/socket.py", line 704, in readinto
    return self._sock.recv_into(b)
  File "/Users/suhuangyuan/miniconda3/envs/resource/lib/python3.9/ssl.py", line 1275, in recv_into
    return self.read(nbytes, buffer)
  File "/Users/suhuangyuan/miniconda3/envs/resource/lib/python3.9/ssl.py", line 1133, in read
    return self._sslobj.read(len, buffer)
urllib3.exceptions.ProtocolError: ('Connection aborted.', TimeoutError(60, 'Operation timed out'))

During handling of the above exception, another exception occurred:

Traceback (most recent call last):
  File "/Users/suhuangyuan/miniconda3/envs/resource/lib/python3.9/site-packages/wandb/sdk/internal/internal_api.py", line 2758, in upload_file
    response = self._upload_file_session.put(
  File "/Users/suhuangyuan/miniconda3/envs/resource/lib/python3.9/site-packages/requests/sessions.py", line 649, in put
    return self.request("PUT", url, data=data, **kwargs)
  File "/Users/suhuangyuan/miniconda3/envs/resource/lib/python3.9/site-packages/requests/sessions.py", line 589, in request
    resp = self.send(prep, **send_kwargs)
  File "/Users/suhuangyuan/miniconda3/envs/resource/lib/python3.9/site-packages/requests/sessions.py", line 703, in send
    r = adapter.send(request, **kwargs)
  File "/Users/suhuangyuan/miniconda3/envs/resource/lib/python3.9/site-packages/requests/adapters.py", line 501, in send
    raise ConnectionError(err, request=request)
requests.exceptions.ConnectionError: ('Connection aborted.', TimeoutError(60, 'Operation timed out'))

During handling of the above exception, another exception occurred:

Traceback (most recent call last):
  File "/Users/suhuangyuan/miniconda3/envs/resource/lib/python3.9/site-packages/wandb/sdk/lib/retry.py", line 131, in __call__
    result = self._call_fn(*args, **kwargs)
  File "/Users/suhuangyuan/miniconda3/envs/resource/lib/python3.9/site-packages/wandb/sdk/internal/internal_api.py", line 2789, in upload_file
    raise _e.with_traceback(sys.exc_info()[2])
  File "/Users/suhuangyuan/miniconda3/envs/resource/lib/python3.9/site-packages/wandb/sdk/internal/internal_api.py", line 2758, in upload_file
    response = self._upload_file_session.put(
  File "/Users/suhuangyuan/miniconda3/envs/resource/lib/python3.9/site-packages/requests/sessions.py", line 649, in put
    return self.request("PUT", url, data=data, **kwargs)
  File "/Users/suhuangyuan/miniconda3/envs/resource/lib/python3.9/site-packages/requests/sessions.py", line 589, in request
    resp = self.send(prep, **send_kwargs)
  File "/Users/suhuangyuan/miniconda3/envs/resource/lib/python3.9/site-packages/requests/sessions.py", line 703, in send
    r = adapter.send(request, **kwargs)
  File "/Users/suhuangyuan/miniconda3/envs/resource/lib/python3.9/site-packages/requests/adapters.py", line 501, in send
    raise ConnectionError(err, request=request)
wandb.sdk.lib.retry.TransientError: None

During handling of the above exception, another exception occurred:

Traceback (most recent call last):
  File "/Users/suhuangyuan/miniconda3/envs/resource/lib/python3.9/site-packages/wandb/apis/normalize.py", line 41, in wrapper
    return func(*args, **kwargs)
  File "/Users/suhuangyuan/miniconda3/envs/resource/lib/python3.9/site-packages/wandb/sdk/lib/retry.py", line 212, in wrapped_fn
    return retrier(*args, **kargs)
  File "/Users/suhuangyuan/miniconda3/envs/resource/lib/python3.9/site-packages/wandb/sdk/lib/retry.py", line 183, in __call__
    wandb.termlog(
  File "/Users/suhuangyuan/miniconda3/envs/resource/lib/python3.9/site-packages/wandb/errors/term.py", line 39, in termlog
    _log(
  File "/Users/suhuangyuan/miniconda3/envs/resource/lib/python3.9/site-packages/wandb/errors/term.py", line 95, in _log
    click.echo(line, file=sys.stderr, nl=newline)
  File "/Users/suhuangyuan/miniconda3/envs/resource/lib/python3.9/site-packages/click/utils.py", line 318, in echo
    file.write(out)  # type: ignore
OSError: [Errno 5] Input/output error

During handling of the above exception, another exception occurred:

Traceback (most recent call last):
  File "/Users/suhuangyuan/miniconda3/envs/resource/lib/python3.9/site-packages/wandb/filesync/upload_job.py", line 125, in push
    self._api.upload_file_retry(
  File "/Users/suhuangyuan/miniconda3/envs/resource/lib/python3.9/site-packages/wandb/apis/normalize.py", line 87, in wrapper
    raise CommError(message, err).with_traceback(sys.exc_info()[2])
  File "/Users/suhuangyuan/miniconda3/envs/resource/lib/python3.9/site-packages/wandb/apis/normalize.py", line 41, in wrapper
    return func(*args, **kwargs)
  File "/Users/suhuangyuan/miniconda3/envs/resource/lib/python3.9/site-packages/wandb/sdk/lib/retry.py", line 212, in wrapped_fn
    return retrier(*args, **kargs)
  File "/Users/suhuangyuan/miniconda3/envs/resource/lib/python3.9/site-packages/wandb/sdk/lib/retry.py", line 183, in __call__
    wandb.termlog(
  File "/Users/suhuangyuan/miniconda3/envs/resource/lib/python3.9/site-packages/wandb/errors/term.py", line 39, in termlog
    _log(
  File "/Users/suhuangyuan/miniconda3/envs/resource/lib/python3.9/site-packages/wandb/errors/term.py", line 95, in _log
    click.echo(line, file=sys.stderr, nl=newline)
  File "/Users/suhuangyuan/miniconda3/envs/resource/lib/python3.9/site-packages/click/utils.py", line 318, in echo
    file.write(out)  # type: ignore
wandb.errors.CommError: [Errno 5] Input/output error

During handling of the above exception, another exception occurred:

Traceback (most recent call last):
  File "/Users/suhuangyuan/miniconda3/envs/resource/lib/python3.9/concurrent/futures/thread.py", line 58, in run
    result = self.fn(*self.args, **self.kwargs)
  File "/Users/suhuangyuan/miniconda3/envs/resource/lib/python3.9/site-packages/wandb/filesync/step_upload.py", line 288, in run_and_notify
    self._do_upload_sync(event)
  File "/Users/suhuangyuan/miniconda3/envs/resource/lib/python3.9/site-packages/wandb/filesync/step_upload.py", line 330, in _do_upload_sync
    job.run()
  File "/Users/suhuangyuan/miniconda3/envs/resource/lib/python3.9/site-packages/wandb/filesync/upload_job.py", line 57, in run
    self.push()
  File "/Users/suhuangyuan/miniconda3/envs/resource/lib/python3.9/site-packages/wandb/filesync/upload_job.py", line 137, in push
    wandb.termerror(
  File "/Users/suhuangyuan/miniconda3/envs/resource/lib/python3.9/site-packages/wandb/errors/term.py", line 61, in termerror
    _log(
  File "/Users/suhuangyuan/miniconda3/envs/resource/lib/python3.9/site-packages/wandb/errors/term.py", line 95, in _log
    click.echo(line, file=sys.stderr, nl=newline)
  File "/Users/suhuangyuan/miniconda3/envs/resource/lib/python3.9/site-packages/click/utils.py", line 318, in echo
    file.write(out)  # type: ignore
OSError: [Errno 5] Input/output error
2024-01-21 06:15:13,925 INFO    SenderThread:19057 [file_stream.py:finish():595] file stream finish called
2024-01-21 06:15:14,330 WARNING FileStreamThread:19057 [file_stream.py:request_with_retry():668] requests_with_retry encountered retryable exception: HTTPSConnectionPool(host='api.wandb.ai', port=443): Read timed out. (read timeout=180). func: functools.partial(<bound method Session.post of <requests.sessions.Session object at 0x12f0340d0>>, timeout=180), args: ('https://api.wandb.ai/files/iris-tajwar/ToM2C/lvkhb8ha/file_stream',), kwargs: {'json': {'files': {'wandb-summary.json': {'offset': 0, 'content': ['{"test/reward": -115.0, "_timestamp": 1705788722.90364, "test/fps": 7.7869818859969335, "_runtime": 15.263533115386963, "_step": 180, "_wandb": {"runtime": 17}}']}}, 'dropped': 0}}
2024-01-21 06:15:17,893 INFO    SenderThread:19057 [file_stream.py:finish():599] file stream finish is done
